Workbook
Name StudentNames: 'Social Skills'!$A$5:$A$19

Sheet Dashboard
A1: SPED Service Compliance Dashboard
A2: Auto-calculated from Year Summary data
A4: Service Type | B4: Total Students | C4: On Track (≥80%) | D4: Behind (50-79%) | E4: At Risk (<50%) | F4: Overall % | G4: Status
A5: Social Skills | B5: =COUNTA('Year Summary'!L5:L19) | C5: =COUNTIF('Year Summary'!L5:L19,">="&0.8) | D5: =COUNTIFS('Year Summary'!L5:L19,">="&0.5,'Year Summary'!L5:L19,"<"&0.8) | E5: =COUNTIF('Year Summary'!L5:L19,"<"&0.5) | F5: =IF(COUNTA('Year Summary'!L5:L19)=0,"",AVERAGE('Year Summary'!L5:L19)) | G5: =IF(F5="","",IF(F5>=0.8,"On Track",IF(F5>=0.5,"Behind","At Risk")))
A6: Speech | B6: =COUNTA('Year Summary'!L23:L37) | C6: =COUNTIF('Year Summary'!L23:L37,">="&0.8) | D6: =COUNTIFS('Year Summary'!L23:L37,">="&0.5,'Year Summary'!L23:L37,"<"&0.8) | E6: =COUNTIF('Year Summary'!L23:L37,"<"&0.5) | F6: =IF(COUNTA('Year Summary'!L23:L37)=0,"",AVERAGE('Year Summary'!L23:L37)) | G6: =IF(F6="","",IF(F6>=0.8,"On Track",IF(F6>=0.5,"Behind","At Risk")))
A7: OT | B7: =COUNTA('Year Summary'!L41:L55) | C7: =COUNTIF('Year Summary'!L41:L55,">="&0.8) | D7: =COUNTIFS('Year Summary'!L41:L55,">="&0.5,'Year Summary'!L41:L55,"<"&0.8) | E7: =COUNTIF('Year Summary'!L41:L55,"<"&0.5) | F7: =IF(COUNTA('Year Summary'!L41:L55)=0,"",AVERAGE('Year Summary'!L41:L55)) | G7: =IF(F7="","",IF(F7>=0.8,"On Track",IF(F7>=0.5,"Behind","At Risk")))
A8: Counseling | B8: =COUNTA('Year Summary'!L59:L73) | C8: =COUNTIF('Year Summary'!L59:L73,">="&0.8) | D8: =COUNTIFS('Year Summary'!L59:L73,">="&0.5,'Year Summary'!L59:L73,"<"&0.8) | E8: =COUNTIF('Year Summary'!L59:L73,"<"&0.5) | F8: =IF(COUNTA('Year Summary'!L59:L73)=0,"",AVERAGE('Year Summary'!L59:L73)) | G8: =IF(F8="","",IF(F8>=0.8,"On Track",IF(F8>=0.5,"Behind","At Risk")))
A9: Inclusion Support | B9: =COUNTA('Year Summary'!L77:L91) | C9: =COUNTIF('Year Summary'!L77:L91,">="&0.8) | D9: =COUNTIFS('Year Summary'!L77:L91,">="&0.5,'Year Summary'!L77:L91,"<"&0.8) | E9: =COUNTIF('Year Summary'!L77:L91,"<"&0.5) | F9: =IF(COUNTA('Year Summary'!L77:L91)=0,"",AVERAGE('Year Summary'!L77:L91)) | G9: =IF(F9="","",IF(F9>=0.8,"On Track",IF(F9>=0.5,"Behind","At Risk")))
A11: ALL SERVICES | B11: =SUM(B5:B9) | C11: =SUM(C5:C9) | D11: =SUM(D5:D9) | E11: =SUM(E5:E9) | F11: =IF(COUNT(F5:F9)=0,"",AVERAGE(F5:F9))

Sheet Social Skills
A1: Social Skills — SPED Minute Tracker
A3: Q1 — Quarter 1
A4: Student Name | B4: Sess 1 | C4: Att 1 | D4: Sess 2 | E4: Att 2 | F4: Sess 3 | G4: Att 3 | H4: Sess 4 | I4: Att 4 | J4: Sess 5 | K4: Att 5 | L4: Sess 6 | M4: Att 6 | N4: Sess 7 | O4: Att 7 | P4: Sess 8 | Q4: Att 8 | R4: Sess 9 | S4: Att 9 | T4: Sess 10 | U4: Att 10 | V4: Min Met | W4: Sess Att | X4: Absences | Y4: IEP Req | Z4: Min Remain | AA4: % Complete | AB4: Pace Needed | AC4: Projected
A5: Raya Hightower | V5: =SUM(B5,D5,F5,H5,J5,L5,N5,P5,R5,T5) | W5: =COUNTIF(C5,"P")+COUNTIF(E5,"P")+COUNTIF(G5,"P")+COUNTIF(I5,"P")+COUNTIF(K5,"P")+COUNTIF(M5,"P")+COUNTIF(O5,"P")+COUNTIF(Q5,"P")+COUNTIF(S5,"P")+COUNTIF(U5,"P") | X5: =COUNTIF(C5,"A")+COUNTIF(E5,"A")+COUNTIF(G5,"A")+COUNTIF(I5,"A")+COUNTIF(K5,"A")+COUNTIF(M5,"A")+COUNTIF(O5,"A")+COUNTIF(Q5,"A")+COUNTIF(S5,"A")+COUNTIF(U5,"A") | Z5: =IF(Y5="","",Y5-V5) | AA5: =IF(OR(Y5="",Y5=0),"",V5/Y5) | AB5: =IF(OR(Y5="",Y5=0),"",IF((10-W5-X5)<=0,"N/A",Z5/(10-W5-X5))) | AC5: =IF(W5=0,"",ROUND((V5/W5)*10,0))
A6: Anu Vijay Anand | V6: =SUM(B6,D6,F6,H6,J6,L6,N6,P6,R6,T6) | W6: =COUNTIF(C6,"P")+COUNTIF(E6,"P")+COUNTIF(G6,"P")+COUNTIF(I6,"P")+COUNTIF(K6,"P")+COUNTIF(M6,"P")+COUNTIF(O6,"P")+COUNTIF(Q6,"P")+COUNTIF(S6,"P")+COUNTIF(U6,"P") | X6: =COUNTIF(C6,"A")+COUNTIF(E6,"A")+COUNTIF(G6,"A")+COUNTIF(I6,"A")+COUNTIF(K6,"A")+COUNTIF(M6,"A")+COUNTIF(O6,"A")+COUNTIF(Q6,"A")+COUNTIF(S6,"A")+COUNTIF(U6,"A") | Z6: =IF(Y6="","",Y6-V6) | AA6: =IF(OR(Y6="",Y6=0),"",V6/Y6) | AB6: =IF(OR(Y6="",Y6=0),"",IF((10-W6-X6)<=0,"N/A",Z6/(10-W6-X6))) | AC6: =IF(W6=0,"",ROUND((V6/W6)*10,0))
A7: Aadhya Gone | V7: =SUM(B7,D7,F7,H7,J7,L7,N7,P7,R7,T7) | W7: =COUNTIF(C7,"P")+COUNTIF(E7,"P")+COUNTIF(G7,"P")+COUNTIF(I7,"P")+COUNTIF(K7,"P")+COUNTIF(M7,"P")+COUNTIF(O7,"P")+COUNTIF(Q7,"P")+COUNTIF(S7,"P")+COUNTIF(U7,"P") | X7: =COUNTIF(C7,"A")+COUNTIF(E7,"A")+COUNTIF(G7,"A")+COUNTIF(I7,"A")+COUNTIF(K7,"A")+COUNTIF(M7,"A")+COUNTIF(O7,"A")+COUNTIF(Q7,"A")+COUNTIF(S7,"A")+COUNTIF(U7,"A") | Z7: =IF(Y7="","",Y7-V7) | AA7: =IF(OR(Y7="",Y7=0),"",V7/Y7) | AB7: =IF(OR(Y7="",Y7=0),"",IF((10-W7-X7)<=0,"N/A",Z7/(10-W7-X7))) | AC7: =IF(W7=0,"",ROUND((V7/W7)*10,0))
A8: Sumeyah Khan | V8: =SUM(B8,D8,F8,H8,J8,L8,N8,P8,R8,T8) | W8: =COUNTIF(C8,"P")+COUNTIF(E8,"P")+COUNTIF(G8,"P")+COUNTIF(I8,"P")+COUNTIF(K8,"P")+COUNTIF(M8,"P")+COUNTIF(O8,"P")+COUNTIF(Q8,"P")+COUNTIF(S8,"P")+COUNTIF(U8,"P") | X8: =COUNTIF(C8,"A")+COUNTIF(E8,"A")+COUNTIF(G8,"A")+COUNTIF(I8,"A")+COUNTIF(K8,"A")+COUNTIF(M8,"A")+COUNTIF(O8,"A")+COUNTIF(Q8,"A")+COUNTIF(S8,"A")+COUNTIF(U8,"A") | Z8: =IF(Y8="","",Y8-V8) | AA8: =IF(OR(Y8="",Y8=0),"",V8/Y8) | AB8: =IF(OR(Y8="",Y8=0),"",IF((10-W8-X8)<=0,"N/A",Z8/(10-W8-X8))) | AC8: =IF(W8=0,"",ROUND((V8/W8)*10,0))
A9: Maria Mujeeb | V9: =SUM(B9,D9,F9,H9,J9,L9,N9,P9,R9,T9) | W9: =COUNTIF(C9,"P")+COUNTIF(E9,"P")+COUNTIF(G9,"P")+COUNTIF(I9,"P")+COUNTIF(K9,"P")+COUNTIF(M9,"P")+COUNTIF(O9,"P")+COUNTIF(Q9,"P")+COUNTIF(S9,"P")+COUNTIF(U9,"P") | X9: =COUNTIF(C9,"A")+COUNTIF(E9,"A")+COUNTIF(G9,"A")+COUNTIF(I9,"A")+COUNTIF(K9,"A")+COUNTIF(M9,"A")+COUNTIF(O9,"A")+COUNTIF(Q9,"A")+COUNTIF(S9,"A")+COUNTIF(U9,"A") | Z9: =IF(Y9="","",Y9-V9) | AA9: =IF(OR(Y9="",Y9=0),"",V9/Y9) | AB9: =IF(OR(Y9="",Y9=0),"",IF((10-W9-X9)<=0,"N/A",Z9/(10-W9-X9))) | AC9: =IF(W9=0,"",ROUND((V9/W9)*10,0))
A10: Jace Ratliff | V10: =SUM(B10,D10,F10,H10,J10,L10,N10,P10,R10,T10) | W10: =COUNTIF(C10,"P")+COUNTIF(E10,"P")+COUNTIF(G10,"P")+COUNTIF(I10,"P")+COUNTIF(K10,"P")+COUNTIF(M10,"P")+COUNTIF(O10,"P")+COUNTIF(Q10,"P")+COUNTIF(S10,"P")+COUNTIF(U10,"P") | X10: =COUNTIF(C10,"A")+COUNTIF(E10,"A")+COUNTIF(G10,"A")+COUNTIF(I10,"A")+COUNTIF(K10,"A")+COUNTIF(M10,"A")+COUNTIF(O10,"A")+COUNTIF(Q10,"A")+COUNTIF(S10,"A")+COUNTIF(U10,"A") | Z10: =IF(Y10="","",Y10-V10) | AA10: =IF(OR(Y10="",Y10=0),"",V10/Y10) | AB10: =IF(OR(Y10="",Y10=0),"",IF((10-W10-X10)<=0,"N/A",Z10/(10-W10-X10))) | AC10: =IF(W10=0,"",ROUND((V10/W10)*10,0))
A11: Evan Allen | V11: =SUM(B11,D11,F11,H11,J11,L11,N11,P11,R11,T11) | W11: =COUNTIF(C11,"P")+COUNTIF(E11,"P")+COUNTIF(G11,"P")+COUNTIF(I11,"P")+COUNTIF(K11,"P")+COUNTIF(M11,"P")+COUNTIF(O11,"P")+COUNTIF(Q11,"P")+COUNTIF(S11,"P")+COUNTIF(U11,"P") | X11: =COUNTIF(C11,"A")+COUNTIF(E11,"A")+COUNTIF(G11,"A")+COUNTIF(I11,"A")+COUNTIF(K11,"A")+COUNTIF(M11,"A")+COUNTIF(O11,"A")+COUNTIF(Q11,"A")+COUNTIF(S11,"A")+COUNTIF(U11,"A") | Z11: =IF(Y11="","",Y11-V11) | AA11: =IF(OR(Y11="",Y11=0),"",V11/Y11) | AB11: =IF(OR(Y11="",Y11=0),"",IF((10-W11-X11)<=0,"N/A",Z11/(10-W11-X11))) | AC11: =IF(W11=0,"",ROUND((V11/W11)*10,0))
A12: Sai Neelagiri | V12: =SUM(B12,D12,F12,H12,J12,L12,N12,P12,R12,T12) | W12: =COUNTIF(C12,"P")+COUNTIF(E12,"P")+COUNTIF(G12,"P")+COUNTIF(I12,"P")+COUNTIF(K12,"P")+COUNTIF(M12,"P")+COUNTIF(O12,"P")+COUNTIF(Q12,"P")+COUNTIF(S12,"P")+COUNTIF(U12,"P") | X12: =COUNTIF(C12,"A")+COUNTIF(E12,"A")+COUNTIF(G12,"A")+COUNTIF(I12,"A")+COUNTIF(K12,"A")+COUNTIF(M12,"A")+COUNTIF(O12,"A")+COUNTIF(Q12,"A")+COUNTIF(S12,"A")+COUNTIF(U12,"A") | Z12: =IF(Y12="","",Y12-V12) | AA12: =IF(OR(Y12="",Y12=0),"",V12/Y12) | AB12: =IF(OR(Y12="",Y12=0),"",IF((10-W12-X12)<=0,"N/A",Z12/(10-W12-X12))) | AC12: =IF(W12=0,"",ROUND((V12/W12)*10,0))
A13: Fletcher Meese | V13: =SUM(B13,D13,F13,H13,J13,L13,N13,P13,R13,T13) | W13: =COUNTIF(C13,"P")+COUNTIF(E13,"P")+COUNTIF(G13,"P")+COUNTIF(I13,"P")+COUNTIF(K13,"P")+COUNTIF(M13,"P")+COUNTIF(O13,"P")+COUNTIF(Q13,"P")+COUNTIF(S13,"P")+COUNTIF(U13,"P") | X13: =COUNTIF(C13,"A")+COUNTIF(E13,"A")+COUNTIF(G13,"A")+COUNTIF(I13,"A")+COUNTIF(K13,"A")+COUNTIF(M13,"A")+COUNTIF(O13,"A")+COUNTIF(Q13,"A")+COUNTIF(S13,"A")+COUNTIF(U13,"A") | Z13: =IF(Y13="","",Y13-V13) | AA13: =IF(OR(Y13="",Y13=0),"",V13/Y13) | AB13: =IF(OR(Y13="",Y13=0),"",IF((10-W13-X13)<=0,"N/A",Z13/(10-W13-X13))) | AC13: =IF(W13=0,"",ROUND((V13/W13)*10,0))
A14: Elijah Aldaco | V14: =SUM(B14,D14,F14,H14,J14,L14,N14,P14,R14,T14) | W14: =COUNTIF(C14,"P")+COUNTIF(E14,"P")+COUNTIF(G14,"P")+COUNTIF(I14,"P")+COUNTIF(K14,"P")+COUNTIF(M14,"P")+COUNTIF(O14,"P")+COUNTIF(Q14,"P")+COUNTIF(S14,"P")+COUNTIF(U14,"P") | X14: =COUNTIF(C14,"A")+COUNTIF(E14,"A")+COUNTIF(G14,"A")+COUNTIF(I14,"A")+COUNTIF(K14,"A")+COUNTIF(M14,"A")+COUNTIF(O14,"A")+COUNTIF(Q14,"A")+COUNTIF(S14,"A")+COUNTIF(U14,"A") | Z14: =IF(Y14="","",Y14-V14) | AA14: =IF(OR(Y14="",Y14=0),"",V14/Y14) | AB14: =IF(OR(Y14="",Y14=0),"",IF((10-W14-X14)<=0,"N/A",Z14/(10-W14-X14))) | AC14: =IF(W14=0,"",ROUND((V14/W14)*10,0))
A15: Cain Gutierrez | V15: =SUM(B15,D15,F15,H15,J15,L15,N15,P15,R15,T15) | W15: =COUNTIF(C15,"P")+COUNTIF(E15,"P")+COUNTIF(G15,"P")+COUNTIF(I15,"P")+COUNTIF(K15,"P")+COUNTIF(M15,"P")+COUNTIF(O15,"P")+COUNTIF(Q15,"P")+COUNTIF(S15,"P")+COUNTIF(U15,"P") | X15: =COUNTIF(C15,"A")+COUNTIF(E15,"A")+COUNTIF(G15,"A")+COUNTIF(I15,"A")+COUNTIF(K15,"A")+COUNTIF(M15,"A")+COUNTIF(O15,"A")+COUNTIF(Q15,"A")+COUNTIF(S15,"A")+COUNTIF(U15,"A") | Z15: =IF(Y15="","",Y15-V15) | AA15: =IF(OR(Y15="",Y15=0),"",V15/Y15) | AB15: =IF(OR(Y15="",Y15=0),"",IF((10-W15-X15)<=0,"N/A",Z15/(10-W15-X15))) | AC15: =IF(W15=0,"",ROUND((V15/W15)*10,0))
A16: Grayson Barnhart | V16: =SUM(B16,D16,F16,H16,J16,L16,N16,P16,R16,T16) | W16: =COUNTIF(C16,"P")+COUNTIF(E16,"P")+COUNTIF(G16,"P")+COUNTIF(I16,"P")+COUNTIF(K16,"P")+COUNTIF(M16,"P")+COUNTIF(O16,"P")+COUNTIF(Q16,"P")+COUNTIF(S16,"P")+COUNTIF(U16,"P") | X16: =COUNTIF(C16,"A")+COUNTIF(E16,"A")+COUNTIF(G16,"A")+COUNTIF(I16,"A")+COUNTIF(K16,"A")+COUNTIF(M16,"A")+COUNTIF(O16,"A")+COUNTIF(Q16,"A")+COUNTIF(S16,"A")+COUNTIF(U16,"A") | Z16: =IF(Y16="","",Y16-V16) | AA16: =IF(OR(Y16="",Y16=0),"",V16/Y16) | AB16: =IF(OR(Y16="",Y16=0),"",IF((10-W16-X16)<=0,"N/A",Z16/(10-W16-X16))) | AC16: =IF(W16=0,"",ROUND((V16/W16)*10,0))
... A19: Jason Bean | V19: =SUM(B19,D19,F19,H19,J19,L19,N19,P19,R19,T19) | W19: =COUNTIF(C19,"P")+COUNTIF(E19,"P")+COUNTIF(G19,"P")+COUNTIF(I19,"P")+COUNTIF(K19,"P")+COUNTIF(M19,"P")+COUNTIF(O19,"P")+COUNTIF(Q19,"P")+COUNTIF(S19,"P")+COUNTIF(U19,"P") | X19: =COUNTIF(C19,"A")+COUNTIF(E19,"A")+COUNTIF(G19,"A")+COUNTIF(I19,"A")+COUNTIF(K19,"A")+COUNTIF(M19,"A")+COUNTIF(O19,"A")+COUNTIF(Q19,"A")+COUNTIF(S19,"A")+COUNTIF(U19,"A") | Z19: =IF(Y19="","",Y19-V19) | AA19: =IF(OR(Y19="",Y19=0),"",V19/Y19) | AB19: =IF(OR(Y19="",Y19=0),"",IF((10-W19-X19)<=0,"N/A",Z19/(10-W19-X19))) | AC19: =IF(W19=0,"",ROUND((V19/W19)*10,0))
A22: Q2 — Quarter 2
A23: Student Name | B23: Sess 1 | C23: Att 1 | D23: Sess 2 | E23: Att 2 | F23: Sess 3 | G23: Att 3 | H23: Sess 4 | I23: Att 4 | J23: Sess 5 | K23: Att 5 | L23: Sess 6 | M23: Att 6 | N23: Sess 7 | O23: Att 7 | P23: Sess 8 | Q23: Att 8 | R23: Sess 9 | S23: Att 9 | T23: Sess 10 | U23: Att 10 | V23: Min Met | W23: Sess Att | X23: Absences | Y23: IEP Req | Z23: Min Remain | AA23: % Complete | AB23: Pace Needed | AC23: Projected
A24: Raya Hightower | V24: =SUM(B24,D24,F24,H24,J24,L24,N24,P24,R24,T24) | W24: =COUNTIF(C24,"P")+COUNTIF(E24,"P")+COUNTIF(G24,"P")+COUNTIF(I24,"P")+COUNTIF(K24,"P")+COUNTIF(M24,"P")+COUNTIF(O24,"P")+COUNTIF(Q24,"P")+COUNTIF(S24,"P")+COUNTIF(U24,"P") | X24: =COUNTIF(C24,"A")+COUNTIF(E24,"A")+COUNTIF(G24,"A")+COUNTIF(I24,"A")+COUNTIF(K24,"A")+COUNTIF(M24,"A")+COUNTIF(O24,"A")+COUNTIF(Q24,"A")+COUNTIF(S24,"A")+COUNTIF(U24,"A") | Z24: =IF(Y24="","",Y24-V24) | AA24: =IF(OR(Y24="",Y24=0),"",V24/Y24) | AB24: =IF(OR(Y24="",Y24=0),"",IF((10-W24-X24)<=0,"N/A",Z24/(10-W24-X24))) | AC24: =IF(W24=0,"",ROUND((V24/W24)*10,0))
A25: Anu Vijay Anand | V25: =SUM(B25,D25,F25,H25,J25,L25,N25,P25,R25,T25) | W25: =COUNTIF(C25,"P")+COUNTIF(E25,"P")+COUNTIF(G25,"P")+COUNTIF(I25,"P")+COUNTIF(K25,"P")+COUNTIF(M25,"P")+COUNTIF(O25,"P")+COUNTIF(Q25,"P")+COUNTIF(S25,"P")+COUNTIF(U25,"P") | X25: =COUNTIF(C25,"A")+COUNTIF(E25,"A")+COUNTIF(G25,"A")+COUNTIF(I25,"A")+COUNTIF(K25,"A")+COUNTIF(M25,"A")+COUNTIF(O25,"A")+COUNTIF(Q25,"A")+COUNTIF(S25,"A")+COUNTIF(U25,"A") | Z25: =IF(Y25="","",Y25-V25) | AA25: =IF(OR(Y25="",Y25=0),"",V25/Y25) | AB25: =IF(OR(Y25="",Y25=0),"",IF((10-W25-X25)<=0,"N/A",Z25/(10-W25-X25))) | AC25: =IF(W25=0,"",ROUND((V25/W25)*10,0))
A26: Aadhya Gone | V26: =SUM(B26,D26,F26,H26,J26,L26,N26,P26,R26,T26) | W26: =COUNTIF(C26,"P")+COUNTIF(E26,"P")+COUNTIF(G26,"P")+COUNTIF(I26,"P")+COUNTIF(K26,"P")+COUNTIF(M26,"P")+COUNTIF(O26,"P")+COUNTIF(Q26,"P")+COUNTIF(S26,"P")+COUNTIF(U26,"P") | X26: =COUNTIF(C26,"A")+COUNTIF(E26,"A")+COUNTIF(G26,"A")+COUNTIF(I26,"A")+COUNTIF(K26,"A")+COUNTIF(M26,"A")+COUNTIF(O26,"A")+COUNTIF(Q26,"A")+COUNTIF(S26,"A")+COUNTIF(U26,"A") | Z26: =IF(Y26="","",Y26-V26) | AA26: =IF(OR(Y26="",Y26=0),"",V26/Y26) | AB26: =IF(OR(Y26="",Y26=0),"",IF((10-W26-X26)<=0,"N/A",Z26/(10-W26-X26))) | AC26: =IF(W26=0,"",ROUND((V26/W26)*10,0))
A27: Sumeyah Khan | V27: =SUM(B27,D27,F27,H27,J27,L27,N27,P27,R27,T27) | W27: =COUNTIF(C27,"P")+COUNTIF(E27,"P")+COUNTIF(G27,"P")+COUNTIF(I27,"P")+COUNTIF(K27,"P")+COUNTIF(M27,"P")+COUNTIF(O27,"P")+COUNTIF(Q27,"P")+COUNTIF(S27,"P")+COUNTIF(U27,"P") | X27: =COUNTIF(C27,"A")+COUNTIF(E27,"A")+COUNTIF(G27,"A")+COUNTIF(I27,"A")+COUNTIF(K27,"A")+COUNTIF(M27,"A")+COUNTIF(O27,"A")+COUNTIF(Q27,"A")+COUNTIF(S27,"A")+COUNTIF(U27,"A") | Z27: =IF(Y27="","",Y27-V27) | AA27: =IF(OR(Y27="",Y27=0),"",V27/Y27) | AB27: =IF(OR(Y27="",Y27=0),"",IF((10-W27-X27)<=0,"N/A",Z27/(10-W27-X27))) | AC27: =IF(W27=0,"",ROUND((V27/W27)*10,0))
A28: Maria Mujeeb | V28: =SUM(B28,D28,F28,H28,J28,L28,N28,P28,R28,T28) | W28: =COUNTIF(C28,"P")+COUNTIF(E28,"P")+COUNTIF(G28,"P")+COUNTIF(I28,"P")+COUNTIF(K28,"P")+COUNTIF(M28,"P")+COUNTIF(O28,"P")+COUNTIF(Q28,"P")+COUNTIF(S28,"P")+COUNTIF(U28,"P") | X28: =COUNTIF(C28,"A")+COUNTIF(E28,"A")+COUNTIF(G28,"A")+COUNTIF(I28,"A")+COUNTIF(K28,"A")+COUNTIF(M28,"A")+COUNTIF(O28,"A")+COUNTIF(Q28,"A")+COUNTIF(S28,"A")+COUNTIF(U28,"A") | Z28: =IF(Y28="","",Y28-V28) | AA28: =IF(OR(Y28="",Y28=0),"",V28/Y28) | AB28: =IF(OR(Y28="",Y28=0),"",IF((10-W28-X28)<=0,"N/A",Z28/(10-W28-X28))) | AC28: =IF(W28=0,"",ROUND((V28/W28)*10,0))
A29: Jace Ratliff | V29: =SUM(B29,D29,F29,H29,J29,L29,N29,P29,R29,T29) | W29: =COUNTIF(C29,"P")+COUNTIF(E29,"P")+COUNTIF(G29,"P")+COUNTIF(I29,"P")+COUNTIF(K29,"P")+COUNTIF(M29,"P")+COUNTIF(O29,"P")+COUNTIF(Q29,"P")+COUNTIF(S29,"P")+COUNTIF(U29,"P") | X29: =COUNTIF(C29,"A")+COUNTIF(E29,"A")+COUNTIF(G29,"A")+COUNTIF(I29,"A")+COUNTIF(K29,"A")+COUNTIF(M29,"A")+COUNTIF(O29,"A")+COUNTIF(Q29,"A")+COUNTIF(S29,"A")+COUNTIF(U29,"A") | Z29: =IF(Y29="","",Y29-V29) | AA29: =IF(OR(Y29="",Y29=0),"",V29/Y29) | AB29: =IF(OR(Y29="",Y29=0),"",IF((10-W29-X29)<=0,"N/A",Z29/(10-W29-X29))) | AC29: =IF(W29=0,"",ROUND((V29/W29)*10,0))
A30: Evan Allen | V30: =SUM(B30,D30,F30,H30,J30,L30,N30,P30,R30,T30) | W30: =COUNTIF(C30,"P")+COUNTIF(E30,"P")+COUNTIF(G30,"P")+COUNTIF(I30,"P")+COUNTIF(K30,"P")+COUNTIF(M30,"P")+COUNTIF(O30,"P")+COUNTIF(Q30,"P")+COUNTIF(S30,"P")+COUNTIF(U30,"P") | X30: =COUNTIF(C30,"A")+COUNTIF(E30,"A")+COUNTIF(G30,"A")+COUNTIF(I30,"A")+COUNTIF(K30,"A")+COUNTIF(M30,"A")+COUNTIF(O30,"A")+COUNTIF(Q30,"A")+COUNTIF(S30,"A")+COUNTIF(U30,"A") | Z30: =IF(Y30="","",Y30-V30) | AA30: =IF(OR(Y30="",Y30=0),"",V30/Y30) | AB30: =IF(OR(Y30="",Y30=0),"",IF((10-W30-X30)<=0,"N/A",Z30/(10-W30-X30))) | AC30: =IF(W30=0,"",ROUND((V30/W30)*10,0))
A31: Sai Neelagiri | V31: =SUM(B31,D31,F31,H31,J31,L31,N31,P31,R31,T31) | W31: =COUNTIF(C31,"P")+COUNTIF(E31,"P")+COUNTIF(G31,"P")+COUNTIF(I31,"P")+COUNTIF(K31,"P")+COUNTIF(M31,"P")+COUNTIF(O31,"P")+COUNTIF(Q31,"P")+COUNTIF(S31,"P")+COUNTIF(U31,"P") | X31: =COUNTIF(C31,"A")+COUNTIF(E31,"A")+COUNTIF(G31,"A")+COUNTIF(I31,"A")+COUNTIF(K31,"A")+COUNTIF(M31,"A")+COUNTIF(O31,"A")+COUNTIF(Q31,"A")+COUNTIF(S31,"A")+COUNTIF(U31,"A") | Z31: =IF(Y31="","",Y31-V31) | AA31: =IF(OR(Y31="",Y31=0),"",V31/Y31) | AB31: =IF(OR(Y31="",Y31=0),"",IF((10-W31-X31)<=0,"N/A",Z31/(10-W31-X31))) | AC31: =IF(W31=0,"",ROUND((V31/W31)*10,0))
A32: Fletcher Meese | V32: =SUM(B32,D32,F32,H32,J32,L32,N32,P32,R32,T32) | W32: =COUNTIF(C32,"P")+COUNTIF(E32,"P")+COUNTIF(G32,"P")+COUNTIF(I32,"P")+COUNTIF(K32,"P")+COUNTIF(M32,"P")+COUNTIF(O32,"P")+COUNTIF(Q32,"P")+COUNTIF(S32,"P")+COUNTIF(U32,"P") | X32: =COUNTIF(C32,"A")+COUNTIF(E32,"A")+COUNTIF(G32,"A")+COUNTIF(I32,"A")+COUNTIF(K32,"A")+COUNTIF(M32,"A")+COUNTIF(O32,"A")+COUNTIF(Q32,"A")+COUNTIF(S32,"A")+COUNTIF(U32,"A") | Z32: =IF(Y32="","",Y32-V32) | AA32: =IF(OR(Y32="",Y32=0),"",V32/Y32) | AB32: =IF(OR(Y32="",Y32=0),"",IF((10-W32-X32)<=0,"N/A",Z32/(10-W32-X32))) | AC32: =IF(W32=0,"",ROUND((V32/W32)*10,0))
A33: Elijah Aldaco | V33: =SUM(B33,D33,F33,H33,J33,L33,N33,P33,R33,T33) | W33: =COUNTIF(C33,"P")+COUNTIF(E33,"P")+COUNTIF(G33,"P")+COUNTIF(I33,"P")+COUNTIF(K33,"P")+COUNTIF(M33,"P")+COUNTIF(O33,"P")+COUNTIF(Q33,"P")+COUNTIF(S33,"P")+COUNTIF(U33,"P") | X33: =COUNTIF(C33,"A")+COUNTIF(E33,"A")+COUNTIF(G33,"A")+COUNTIF(I33,"A")+COUNTIF(K33,"A")+COUNTIF(M33,"A")+COUNTIF(O33,"A")+COUNTIF(Q33,"A")+COUNTIF(S33,"A")+COUNTIF(U33,"A") | Z33: =IF(Y33="","",Y33-V33) | AA33: =IF(OR(Y33="",Y33=0),"",V33/Y33) | AB33: =IF(OR(Y33="",Y33=0),"",IF((10-W33-X33)<=0,"N/A",Z33/(10-W33-X33))) | AC33: =IF(W33=0,"",ROUND((V33/W33)*10,0))
A34: Cain Gutierrez | V34: =SUM(B34,D34,F34,H34,J34,L34,N34,P34,R34,T34) | W34: =COUNTIF(C34,"P")+COUNTIF(E34,"P")+COUNTIF(G34,"P")+COUNTIF(I34,"P")+COUNTIF(K34,"P")+COUNTIF(M34,"P")+COUNTIF(O34,"P")+COUNTIF(Q34,"P")+COUNTIF(S34,"P")+COUNTIF(U34,"P") | X34: =COUNTIF(C34,"A")+COUNTIF(E34,"A")+COUNTIF(G34,"A")+COUNTIF(I34,"A")+COUNTIF(K34,"A")+COUNTIF(M34,"A")+COUNTIF(O34,"A")+COUNTIF(Q34,"A")+COUNTIF(S34,"A")+COUNTIF(U34,"A") | Z34: =IF(Y34="","",Y34-V34) | AA34: =IF(OR(Y34="",Y34=0),"",V34/Y34) | AB34: =IF(OR(Y34="",Y34=0),"",IF((10-W34-X34)<=0,"N/A",Z34/(10-W34-X34))) | AC34: =IF(W34=0,"",ROUND((V34/W34)*10,0))
A35: Grayson Barnhart | V35: =SUM(B35,D35,F35,H35,J35,L35,N35,P35,R35,T35) | W35: =COUNTIF(C35,"P")+COUNTIF(E35,"P")+COUNTIF(G35,"P")+COUNTIF(I35,"P")+COUNTIF(K35,"P")+COUNTIF(M35,"P")+COUNTIF(O35,"P")+COUNTIF(Q35,"P")+COUNTIF(S35,"P")+COUNTIF(U35,"P") | X35: =COUNTIF(C35,"A")+COUNTIF(E35,"A")+COUNTIF(G35,"A")+COUNTIF(I35,"A")+COUNTIF(K35,"A")+COUNTIF(M35,"A")+COUNTIF(O35,"A")+COUNTIF(Q35,"A")+COUNTIF(S35,"A")+COUNTIF(U35,"A") | Z35: =IF(Y35="","",Y35-V35) | AA35: =IF(OR(Y35="",Y35=0),"",V35/Y35) | AB35: =IF(OR(Y35="",Y35=0),"",IF((10-W35-X35)<=0,"N/A",Z35/(10-W35-X35))) | AC35: =IF(W35=0,"",ROUND((V35/W35)*10,0))
... A38: Jason Bean | V38: =SUM(B38,D38,F38,H38,J38,L38,N38,P38,R38,T38) | W38: =COUNTIF(C38,"P")+COUNTIF(E38,"P")+COUNTIF(G38,"P")+COUNTIF(I38,"P")+COUNTIF(K38,"P")+COUNTIF(M38,"P")+COUNTIF(O38,"P")+COUNTIF(Q38,"P")+COUNTIF(S38,"P")+COUNTIF(U38,"P") | X38: =COUNTIF(C38,"A")+COUNTIF(E38,"A")+COUNTIF(G38,"A")+COUNTIF(I38,"A")+COUNTIF(K38,"A")+COUNTIF(M38,"A")+COUNTIF(O38,"A")+COUNTIF(Q38,"A")+COUNTIF(S38,"A")+COUNTIF(U38,"A") | Z38: =IF(Y38="","",Y38-V38) | AA38: =IF(OR(Y38="",Y38=0),"",V38/Y38) | AB38: =IF(OR(Y38="",Y38=0),"",IF((10-W38-X38)<=0,"N/A",Z38/(10-W38-X38))) | AC38: =IF(W38=0,"",ROUND((V38/W38)*10,0))
A41: Q3 — Quarter 3
A42: Student Name | B42: Sess 1 | C42: Att 1 | D42: Sess 2 | E42: Att 2 | F42: Sess 3 | G42: Att 3 | H42: Sess 4 | I42: Att 4 | J42: Sess 5 | K42: Att 5 | L42: Sess 6 | M42: Att 6 | N42: Sess 7 | O42: Att 7 | P42: Sess 8 | Q42: Att 8 | R42: Sess 9 | S42: Att 9 | T42: Sess 10 | U42: Att 10 | V42: Min Met | W42: Sess Att | X42: Absences | Y42: IEP Req | Z42: Min Remain | AA42: % Complete | AB42: Pace Needed | AC42: Projected
A43: Raya Hightower | V43: =SUM(B43,D43,F43,H43,J43,L43,N43,P43,R43,T43) | W43: =COUNTIF(C43,"P")+COUNTIF(E43,"P")+COUNTIF(G43,"P")+COUNTIF(I43,"P")+COUNTIF(K43,"P")+COUNTIF(M43,"P")+COUNTIF(O43,"P")+COUNTIF(Q43,"P")+COUNTIF(S43,"P")+COUNTIF(U43,"P") | X43: =COUNTIF(C43,"A")+COUNTIF(E43,"A")+COUNTIF(G43,"A")+COUNTIF(I43,"A")+COUNTIF(K43,"A")+COUNTIF(M43,"A")+COUNTIF(O43,"A")+COUNTIF(Q43,"A")+COUNTIF(S43,"A")+COUNTIF(U43,"A") | Z43: =IF(Y43="","",Y43-V43) | AA43: =IF(OR(Y43="",Y43=0),"",V43/Y43) | AB43: =IF(OR(Y43="",Y43=0),"",IF((10-W43-X43)<=0,"N/A",Z43/(10-W43-X43))) | AC43: =IF(W43=0,"",ROUND((V43/W43)*10,0))
A44: Anu Vijay Anand | V44: =SUM(B44,D44,F44,H44,J44,L44,N44,P44,R44,T44) | W44: =COUNTIF(C44,"P")+COUNTIF(E44,"P")+COUNTIF(G44,"P")+COUNTIF(I44,"P")+COUNTIF(K44,"P")+COUNTIF(M44,"P")+COUNTIF(O44,"P")+COUNTIF(Q44,"P")+COUNTIF(S44,"P")+COUNTIF(U44,"P") | X44: =COUNTIF(C44,"A")+COUNTIF(E44,"A")+COUNTIF(G44,"A")+COUNTIF(I44,"A")+COUNTIF(K44,"A")+COUNTIF(M44,"A")+COUNTIF(O44,"A")+COUNTIF(Q44,"A")+COUNTIF(S44,"A")+COUNTIF(U44,"A") | Z44: =IF(Y44="","",Y44-V44) | AA44: =IF(OR(Y44="",Y44=0),"",V44/Y44) | AB44: =IF(OR(Y44="",Y44=0),"",IF((10-W44-X44)<=0,"N/A",Z44/(10-W44-X44))) | AC44: =IF(W44=0,"",ROUND((V44/W44)*10,0))
A45: Aadhya Gone | V45: =SUM(B45,D45,F45,H45,J45,L45,N45,P45,R45,T45) | W45: =COUNTIF(C45,"P")+COUNTIF(E45,"P")+COUNTIF(G45,"P")+COUNTIF(I45,"P")+COUNTIF(K45,"P")+COUNTIF(M45,"P")+COUNTIF(O45,"P")+COUNTIF(Q45,"P")+COUNTIF(S45,"P")+COUNTIF(U45,"P") | X45: =COUNTIF(C45,"A")+COUNTIF(E45,"A")+COUNTIF(G45,"A")+COUNTIF(I45,"A")+COUNTIF(K45,"A")+COUNTIF(M45,"A")+COUNTIF(O45,"A")+COUNTIF(Q45,"A")+COUNTIF(S45,"A")+COUNTIF(U45,"A") | Z45: =IF(Y45="","",Y45-V45) | AA45: =IF(OR(Y45="",Y45=0),"",V45/Y45) | AB45: =IF(OR(Y45="",Y45=0),"",IF((10-W45-X45)<=0,"N/A",Z45/(10-W45-X45))) | AC45: =IF(W45=0,"",ROUND((V45/W45)*10,0))
A46: Sumeyah Khan | V46: =SUM(B46,D46,F46,H46,J46,L46,N46,P46,R46,T46) | W46: =COUNTIF(C46,"P")+COUNTIF(E46,"P")+COUNTIF(G46,"P")+COUNTIF(I46,"P")+COUNTIF(K46,"P")+COUNTIF(M46,"P")+COUNTIF(O46,"P")+COUNTIF(Q46,"P")+COUNTIF(S46,"P")+COUNTIF(U46,"P") | X46: =COUNTIF(C46,"A")+COUNTIF(E46,"A")+COUNTIF(G46,"A")+COUNTIF(I46,"A")+COUNTIF(K46,"A")+COUNTIF(M46,"A")+COUNTIF(O46,"A")+COUNTIF(Q46,"A")+COUNTIF(S46,"A")+COUNTIF(U46,"A") | Z46: =IF(Y46="","",Y46-V46) | AA46: =IF(OR(Y46="",Y46=0),"",V46/Y46) | AB46: =IF(OR(Y46="",Y46=0),"",IF((10-W46-X46)<=0,"N/A",Z46/(10-W46-X46))) | AC46: =IF(W46=0,"",ROUND((V46/W46)*10,0))
A47: Maria Mujeeb | V47: =SUM(B47,D47,F47,H47,J47,L47,N47,P47,R47,T47) | W47: =COUNTIF(C47,"P")+COUNTIF(E47,"P")+COUNTIF(G47,"P")+COUNTIF(I47,"P")+COUNTIF(K47,"P")+COUNTIF(M47,"P")+COUNTIF(O47,"P")+COUNTIF(Q47,"P")+COUNTIF(S47,"P")+COUNTIF(U47,"P") | X47: =COUNTIF(C47,"A")+COUNTIF(E47,"A")+COUNTIF(G47,"A")+COUNTIF(I47,"A")+COUNTIF(K47,"A")+COUNTIF(M47,"A")+COUNTIF(O47,"A")+COUNTIF(Q47,"A")+COUNTIF(S47,"A")+COUNTIF(U47,"A") | Z47: =IF(Y47="","",Y47-V47) | AA47: =IF(OR(Y47="",Y47=0),"",V47/Y47) | AB47: =IF(OR(Y47="",Y47=0),"",IF((10-W47-X47)<=0,"N/A",Z47/(10-W47-X47))) | AC47: =IF(W47=0,"",ROUND((V47/W47)*10,0))
A48: Jace Ratliff | V48: =SUM(B48,D48,F48,H48,J48,L48,N48,P48,R48,T48) | W48: =COUNTIF(C48,"P")+COUNTIF(E48,"P")+COUNTIF(G48,"P")+COUNTIF(I48,"P")+COUNTIF(K48,"P")+COUNTIF(M48,"P")+COUNTIF(O48,"P")+COUNTIF(Q48,"P")+COUNTIF(S48,"P")+COUNTIF(U48,"P") | X48: =COUNTIF(C48,"A")+COUNTIF(E48,"A")+COUNTIF(G48,"A")+COUNTIF(I48,"A")+COUNTIF(K48,"A")+COUNTIF(M48,"A")+COUNTIF(O48,"A")+COUNTIF(Q48,"A")+COUNTIF(S48,"A")+COUNTIF(U48,"A") | Z48: =IF(Y48="","",Y48-V48) | AA48: =IF(OR(Y48="",Y48=0),"",V48/Y48) | AB48: =IF(OR(Y48="",Y48=0),"",IF((10-W48-X48)<=0,"N/A",Z48/(10-W48-X48))) | AC48: =IF(W48=0,"",ROUND((V48/W48)*10,0))
A49: Evan Allen | V49: =SUM(B49,D49,F49,H49,J49,L49,N49,P49,R49,T49) | W49: =COUNTIF(C49,"P")+COUNTIF(E49,"P")+COUNTIF(G49,"P")+COUNTIF(I49,"P")+COUNTIF(K49,"P")+COUNTIF(M49,"P")+COUNTIF(O49,"P")+COUNTIF(Q49,"P")+COUNTIF(S49,"P")+COUNTIF(U49,"P") | X49: =COUNTIF(C49,"A")+COUNTIF(E49,"A")+COUNTIF(G49,"A")+COUNTIF(I49,"A")+COUNTIF(K49,"A")+COUNTIF(M49,"A")+COUNTIF(O49,"A")+COUNTIF(Q49,"A")+COUNTIF(S49,"A")+COUNTIF(U49,"A") | Z49: =IF(Y49="","",Y49-V49) | AA49: =IF(OR(Y49="",Y49=0),"",V49/Y49) | AB49: =IF(OR(Y49="",Y49=0),"",IF((10-W49-X49)<=0,"N/A",Z49/(10-W49-X49))) | AC49: =IF(W49=0,"",ROUND((V49/W49)*10,0))
...

Sheet Speech
A1: Speech — SPED Minute Tracker
A3: Q1 — Quarter 1
A4: Student Name | B4: Sess 1 | C4: Att 1 | D4: Sess 2 | E4: Att 2 | F4: Sess 3 | G4: Att 3 | H4: Sess 4 | I4: Att 4 | J4: Sess 5 | K4: Att 5 | L4: Sess 6 | M4: Att 6 | N4: Sess 7 | O4: Att 7 | P4: Sess 8 | Q4: Att 8 | R4: Sess 9 | S4: Att 9 | T4: Sess 10 | U4: Att 10 | V4: Min Met | W4: Sess Att | X4: Absences | Y4: IEP Req | Z4: Min Remain | AA4: % Complete | AB4: Pace Needed | AC4: Projected
A5: Raya Hightower | V5: =SUM(B5,D5,F5,H5,J5,L5,N5,P5,R5,T5) | W5: =COUNTIF(C5,"P")+COUNTIF(E5,"P")+COUNTIF(G5,"P")+COUNTIF(I5,"P")+COUNTIF(K5,"P")+COUNTIF(M5,"P")+COUNTIF(O5,"P")+COUNTIF(Q5,"P")+COUNTIF(S5,"P")+COUNTIF(U5,"P") | X5: =COUNTIF(C5,"A")+COUNTIF(E5,"A")+COUNTIF(G5,"A")+COUNTIF(I5,"A")+COUNTIF(K5,"A")+COUNTIF(M5,"A")+COUNTIF(O5,"A")+COUNTIF(Q5,"A")+COUNTIF(S5,"A")+COUNTIF(U5,"A") | Z5: =IF(Y5="","",Y5-V5) | AA5: =IF(OR(Y5="",Y5=0),"",V5/Y5) | AB5: =IF(OR(Y5="",Y5=0),"",IF((10-W5-X5)<=0,"N/A",Z5/(10-W5-X5))) | AC5: =IF(W5=0,"",ROUND((V5/W5)*10,0))
A6: Anu Vijay Anand | V6: =SUM(B6,D6,F6,H6,J6,L6,N6,P6,R6,T6) | W6: =COUNTIF(C6,"P")+COUNTIF(E6,"P")+COUNTIF(G6,"P")+COUNTIF(I6,"P")+COUNTIF(K6,"P")+COUNTIF(M6,"P")+COUNTIF(O6,"P")+COUNTIF(Q6,"P")+COUNTIF(S6,"P")+COUNTIF(U6,"P") | X6: =COUNTIF(C6,"A")+COUNTIF(E6,"A")+COUNTIF(G6,"A")+COUNTIF(I6,"A")+COUNTIF(K6,"A")+COUNTIF(M6,"A")+COUNTIF(O6,"A")+COUNTIF(Q6,"A")+COUNTIF(S6,"A")+COUNTIF(U6,"A") | Z6: =IF(Y6="","",Y6-V6) | AA6: =IF(OR(Y6="",Y6=0),"",V6/Y6) | AB6: =IF(OR(Y6="",Y6=0),"",IF((10-W6-X6)<=0,"N/A",Z6/(10-W6-X6))) | AC6: =IF(W6=0,"",ROUND((V6/W6)*10,0))
A7: Aadhya Gone | V7: =SUM(B7,D7,F7,H7,J7,L7,N7,P7,R7,T7) | W7: =COUNTIF(C7,"P")+COUNTIF(E7,"P")+COUNTIF(G7,"P")+COUNTIF(I7,"P")+COUNTIF(K7,"P")+COUNTIF(M7,"P")+COUNTIF(O7,"P")+COUNTIF(Q7,"P")+COUNTIF(S7,"P")+COUNTIF(U7,"P") | X7: =COUNTIF(C7,"A")+COUNTIF(E7,"A")+COUNTIF(G7,"A")+COUNTIF(I7,"A")+COUNTIF(K7,"A")+COUNTIF(M7,"A")+COUNTIF(O7,"A")+COUNTIF(Q7,"A")+COUNTIF(S7,"A")+COUNTIF(U7,"A") | Z7: =IF(Y7="","",Y7-V7) | AA7: =IF(OR(Y7="",Y7=0),"",V7/Y7) | AB7: =IF(OR(Y7="",Y7=0),"",IF((10-W7-X7)<=0,"N/A",Z7/(10-W7-X7))) | AC7: =IF(W7=0,"",ROUND((V7/W7)*10,0))
A8: Sumeyah Khan | V8: =SUM(B8,D8,F8,H8,J8,L8,N8,P8,R8,T8) | W8: =COUNTIF(C8,"P")+COUNTIF(E8,"P")+COUNTIF(G8,"P")+COUNTIF(I8,"P")+COUNTIF(K8,"P")+COUNTIF(M8,"P")+COUNTIF(O8,"P")+COUNTIF(Q8,"P")+COUNTIF(S8,"P")+COUNTIF(U8,"P") | X8: =COUNTIF(C8,"A")+COUNTIF(E8,"A")+COUNTIF(G8,"A")+COUNTIF(I8,"A")+COUNTIF(K8,"A")+COUNTIF(M8,"A")+COUNTIF(O8,"A")+COUNTIF(Q8,"A")+COUNTIF(S8,"A")+COUNTIF(U8,"A") | Z8: =IF(Y8="","",Y8-V8) | AA8: =IF(OR(Y8="",Y8=0),"",V8/Y8) | AB8: =IF(OR(Y8="",Y8=0),"",IF((10-W8-X8)<=0,"N/A",Z8/(10-W8-X8))) | AC8: =IF(W8=0,"",ROUND((V8/W8)*10,0))
A9: Maria Mujeeb | V9: =SUM(B9,D9,F9,H9,J9,L9,N9,P9,R9,T9) | W9: =COUNTIF(C9,"P")+COUNTIF(E9,"P")+COUNTIF(G9,"P")+COUNTIF(I9,"P")+COUNTIF(K9,"P")+COUNTIF(M9,"P")+COUNTIF(O9,"P")+COUNTIF(Q9,"P")+COUNTIF(S9,"P")+COUNTIF(U9,"P") | X9: =COUNTIF(C9,"A")+COUNTIF(E9,"A")+COUNTIF(G9,"A")+COUNTIF(I9,"A")+COUNTIF(K9,"A")+COUNTIF(M9,"A")+COUNTIF(O9,"A")+COUNTIF(Q9,"A")+COUNTIF(S9,"A")+COUNTIF(U9,"A") | Z9: =IF(Y9="","",Y9-V9) | AA9: =IF(OR(Y9="",Y9=0),"",V9/Y9) | AB9: =IF(OR(Y9="",Y9=0),"",IF((10-W9-X9)<=0,"N/A",Z9/(10-W9-X9))) | AC9: =IF(W9=0,"",ROUND((V9/W9)*10,0))
A10: Jace Ratliff | V10: =SUM(B10,D10,F10,H10,J10,L10,N10,P10,R10,T10) | W10: =COUNTIF(C10,"P")+COUNTIF(E10,"P")+COUNTIF(G10,"P")+COUNTIF(I10,"P")+COUNTIF(K10,"P")+COUNTIF(M10,"P")+COUNTIF(O10,"P")+COUNTIF(Q10,"P")+COUNTIF(S10,"P")+COUNTIF(U10,"P") | X10: =COUNTIF(C10,"A")+COUNTIF(E10,"A")+COUNTIF(G10,"A")+COUNTIF(I10,"A")+COUNTIF(K10,"A")+COUNTIF(M10,"A")+COUNTIF(O10,"A")+COUNTIF(Q10,"A")+COUNTIF(S10,"A")+COUNTIF(U10,"A") | Z10: =IF(Y10="","",Y10-V10) | AA10: =IF(OR(Y10="",Y10=0),"",V10/Y10) | AB10: =IF(OR(Y10="",Y10=0),"",IF((10-W10-X10)<=0,"N/A",Z10/(10-W10-X10))) | AC10: =IF(W10=0,"",ROUND((V10/W10)*10,0))
A11: Evan Allen | V11: =SUM(B11,D11,F11,H11,J11,L11,N11,P11,R11,T11) | W11: =COUNTIF(C11,"P")+COUNTIF(E11,"P")+COUNTIF(G11,"P")+COUNTIF(I11,"P")+COUNTIF(K11,"P")+COUNTIF(M11,"P")+COUNTIF(O11,"P")+COUNTIF(Q11,"P")+COUNTIF(S11,"P")+COUNTIF(U11,"P") | X11: =COUNTIF(C11,"A")+COUNTIF(E11,"A")+COUNTIF(G11,"A")+COUNTIF(I11,"A")+COUNTIF(K11,"A")+COUNTIF(M11,"A")+COUNTIF(O11,"A")+COUNTIF(Q11,"A")+COUNTIF(S11,"A")+COUNTIF(U11,"A") | Z11: =IF(Y11="","",Y11-V11) | AA11: =IF(OR(Y11="",Y11=0),"",V11/Y11) | AB11: =IF(OR(Y11="",Y11=0),"",IF((10-W11-X11)<=0,"N/A",Z11/(10-W11-X11))) | AC11: =IF(W11=0,"",ROUND((V11/W11)*10,0))
A12: Sai Neelagiri | V12: =SUM(B12,D12,F12,H12,J12,L12,N12,P12,R12,T12) | W12: =COUNTIF(C12,"P")+COUNTIF(E12,"P")+COUNTIF(G12,"P")+COUNTIF(I12,"P")+COUNTIF(K12,"P")+COUNTIF(M12,"P")+COUNTIF(O12,"P")+COUNTIF(Q12,"P")+COUNTIF(S12,"P")+COUNTIF(U12,"P") | X12: =COUNTIF(C12,"A")+COUNTIF(E12,"A")+COUNTIF(G12,"A")+COUNTIF(I12,"A")+COUNTIF(K12,"A")+COUNTIF(M12,"A")+COUNTIF(O12,"A")+COUNTIF(Q12,"A")+COUNTIF(S12,"A")+COUNTIF(U12,"A") | Z12: =IF(Y12="","",Y12-V12) | AA12: =IF(OR(Y12="",Y12=0),"",V12/Y12) | AB12: =IF(OR(Y12="",Y12=0),"",IF((10-W12-X12)<=0,"N/A",Z12/(10-W12-X12))) | AC12: =IF(W12=0,"",ROUND((V12/W12)*10,0))
A13: Fletcher Meese | V13: =SUM(B13,D13,F13,H13,J13,L13,N13,P13,R13,T13) | W13: =COUNTIF(C13,"P")+COUNTIF(E13,"P")+COUNTIF(G13,"P")+COUNTIF(I13,"P")+COUNTIF(K13,"P")+COUNTIF(M13,"P")+COUNTIF(O13,"P")+COUNTIF(Q13,"P")+COUNTIF(S13,"P")+COUNTIF(U13,"P") | X13: =COUNTIF(C13,"A")+COUNTIF(E13,"A")+COUNTIF(G13,"A")+COUNTIF(I13,"A")+COUNTIF(K13,"A")+COUNTIF(M13,"A")+COUNTIF(O13,"A")+COUNTIF(Q13,"A")+COUNTIF(S13,"A")+COUNTIF(U13,"A") | Z13: =IF(Y13="","",Y13-V13) | AA13: =IF(OR(Y13="",Y13=0),"",V13/Y13) | AB13: =IF(OR(Y13="",Y13=0),"",IF((10-W13-X13)<=0,"N/A",Z13/(10-W13-X13))) | AC13: =IF(W13=0,"",ROUND((V13/W13)*10,0))
A14: Elijah Aldaco | V14: =SUM(B14,D14,F14,H14,J14,L14,N14,P14,R14,T14) | W14: =COUNTIF(C14,"P")+COUNTIF(E14,"P")+COUNTIF(G14,"P")+COUNTIF(I14,"P")+COUNTIF(K14,"P")+COUNTIF(M14,"P")+COUNTIF(O14,"P")+COUNTIF(Q14,"P")+COUNTIF(S14,"P")+COUNTIF(U14,"P") | X14: =COUNTIF(C14,"A")+COUNTIF(E14,"A")+COUNTIF(G14,"A")+COUNTIF(I14,"A")+COUNTIF(K14,"A")+COUNTIF(M14,"A")+COUNTIF(O14,"A")+COUNTIF(Q14,"A")+COUNTIF(S14,"A")+COUNTIF(U14,"A") | Z14: =IF(Y14="","",Y14-V14) | AA14: =IF(OR(Y14="",Y14=0),"",V14/Y14) | AB14: =IF(OR(Y14="",Y14=0),"",IF((10-W14-X14)<=0,"N/A",Z14/(10-W14-X14))) | AC14: =IF(W14=0,"",ROUND((V14/W14)*10,0))
A15: Cain Gutierrez | V15: =SUM(B15,D15,F15,H15,J15,L15,N15,P15,R15,T15) | W15: =COUNTIF(C15,"P")+COUNTIF(E15,"P")+COUNTIF(G15,"P")+COUNTIF(I15,"P")+COUNTIF(K15,"P")+COUNTIF(M15,"P")+COUNTIF(O15,"P")+COUNTIF(Q15,"P")+COUNTIF(S15,"P")+COUNTIF(U15,"P") | X15: =COUNTIF(C15,"A")+COUNTIF(E15,"A")+COUNTIF(G15,"A")+COUNTIF(I15,"A")+COUNTIF(K15,"A")+COUNTIF(M15,"A")+COUNTIF(O15,"A")+COUNTIF(Q15,"A")+COUNTIF(S15,"A")+COUNTIF(U15,"A") | Z15: =IF(Y15="","",Y15-V15) | AA15: =IF(OR(Y15="",Y15=0),"",V15/Y15) | AB15: =IF(OR(Y15="",Y15=0),"",IF((10-W15-X15)<=0,"N/A",Z15/(10-W15-X15))) | AC15: =IF(W15=0,"",ROUND((V15/W15)*10,0))
A16: Grayson Barnhart | V16: =SUM(B16,D16,F16,H16,J16,L16,N16,P16,R16,T16) | W16: =COUNTIF(C16,"P")+COUNTIF(E16,"P")+COUNTIF(G16,"P")+COUNTIF(I16,"P")+COUNTIF(K16,"P")+COUNTIF(M16,"P")+COUNTIF(O16,"P")+COUNTIF(Q16,"P")+COUNTIF(S16,"P")+COUNTIF(U16,"P") | X16: =COUNTIF(C16,"A")+COUNTIF(E16,"A")+COUNTIF(G16,"A")+COUNTIF(I16,"A")+COUNTIF(K16,"A")+COUNTIF(M16,"A")+COUNTIF(O16,"A")+COUNTIF(Q16,"A")+COUNTIF(S16,"A")+COUNTIF(U16,"A") | Z16: =IF(Y16="","",Y16-V16) | AA16: =IF(OR(Y16="",Y16=0),"",V16/Y16) | AB16: =IF(OR(Y16="",Y16=0),"",IF((10-W16-X16)<=0,"N/A",Z16/(10-W16-X16))) | AC16: =IF(W16=0,"",ROUND((V16/W16)*10,0))
... A19: Jason Bean | V19: =SUM(B19,D19,F19,H19,J19,L19,N19,P19,R19,T19) | W19: =COUNTIF(C19,"P")+COUNTIF(E19,"P")+COUNTIF(G19,"P")+COUNTIF(I19,"P")+COUNTIF(K19,"P")+COUNTIF(M19,"P")+COUNTIF(O19,"P")+COUNTIF(Q19,"P")+COUNTIF(S19,"P")+COUNTIF(U19,"P") | X19: =COUNTIF(C19,"A")+COUNTIF(E19,"A")+COUNTIF(G19,"A")+COUNTIF(I19,"A")+COUNTIF(K19,"A")+COUNTIF(M19,"A")+COUNTIF(O19,"A")+COUNTIF(Q19,"A")+COUNTIF(S19,"A")+COUNTIF(U19,"A") | Z19: =IF(Y19="","",Y19-V19) | AA19: =IF(OR(Y19="",Y19=0),"",V19/Y19) | AB19: =IF(OR(Y19="",Y19=0),"",IF((10-W19-X19)<=0,"N/A",Z19/(10-W19-X19))) | AC19: =IF(W19=0,"",ROUND((V19/W19)*10,0))
A22: Q2 — Quarter 2
A23: Student Name | B23: Sess 1 | C23: Att 1 | D23: Sess 2 | E23: Att 2 | F23: Sess 3 | G23: Att 3 | H23: Sess 4 | I23: Att 4 | J23: Sess 5 | K23: Att 5 | L23: Sess 6 | M23: Att 6 | N23: Sess 7 | O23: Att 7 | P23: Sess 8 | Q23: Att 8 | R23: Sess 9 | S23: Att 9 | T23: Sess 10 | U23: Att 10 | V23: Min Met | W23: Sess Att | X23: Absences | Y23: IEP Req | Z23: Min Remain | AA23: % Complete | AB23: Pace Needed | AC23: Projected
A24: Raya Hightower | V24: =SUM(B24,D24,F24,H24,J24,L24,N24,P24,R24,T24) | W24: =COUNTIF(C24,"P")+COUNTIF(E24,"P")+COUNTIF(G24,"P")+COUNTIF(I24,"P")+COUNTIF(K24,"P")+COUNTIF(M24,"P")+COUNTIF(O24,"P")+COUNTIF(Q24,"P")+COUNTIF(S24,"P")+COUNTIF(U24,"P") | X24: =COUNTIF(C24,"A")+COUNTIF(E24,"A")+COUNTIF(G24,"A")+COUNTIF(I24,"A")+COUNTIF(K24,"A")+COUNTIF(M24,"A")+COUNTIF(O24,"A")+COUNTIF(Q24,"A")+COUNTIF(S24,"A")+COUNTIF(U24,"A") | Z24: =IF(Y24="","",Y24-V24) | AA24: =IF(OR(Y24="",Y24=0),"",V24/Y24) | AB24: =IF(OR(Y24="",Y24=0),"",IF((10-W24-X24)<=0,"N/A",Z24/(10-W24-X24))) | AC24: =IF(W24=0,"",ROUND((V24/W24)*10,0))
A25: Anu Vijay Anand | V25: =SUM(B25,D25,F25,H25,J25,L25,N25,P25,R25,T25) | W25: =COUNTIF(C25,"P")+COUNTIF(E25,"P")+COUNTIF(G25,"P")+COUNTIF(I25,"P")+COUNTIF(K25,"P")+COUNTIF(M25,"P")+COUNTIF(O25,"P")+COUNTIF(Q25,"P")+COUNTIF(S25,"P")+COUNTIF(U25,"P") | X25: =COUNTIF(C25,"A")+COUNTIF(E25,"A")+COUNTIF(G25,"A")+COUNTIF(I25,"A")+COUNTIF(K25,"A")+COUNTIF(M25,"A")+COUNTIF(O25,"A")+COUNTIF(Q25,"A")+COUNTIF(S25,"A")+COUNTIF(U25,"A") | Z25: =IF(Y25="","",Y25-V25) | AA25: =IF(OR(Y25="",Y25=0),"",V25/Y25) | AB25: =IF(OR(Y25="",Y25=0),"",IF((10-W25-X25)<=0,"N/A",Z25/(10-W25-X25))) | AC25: =IF(W25=0,"",ROUND((V25/W25)*10,0))
A26: Aadhya Gone | V26: =SUM(B26,D26,F26,H26,J26,L26,N26,P26,R26,T26) | W26: =COUNTIF(C26,"P")+COUNTIF(E26,"P")+COUNTIF(G26,"P")+COUNTIF(I26,"P")+COUNTIF(K26,"P")+COUNTIF(M26,"P")+COUNTIF(O26,"P")+COUNTIF(Q26,"P")+COUNTIF(S26,"P")+COUNTIF(U26,"P") | X26: =COUNTIF(C26,"A")+COUNTIF(E26,"A")+COUNTIF(G26,"A")+COUNTIF(I26,"A")+COUNTIF(K26,"A")+COUNTIF(M26,"A")+COUNTIF(O26,"A")+COUNTIF(Q26,"A")+COUNTIF(S26,"A")+COUNTIF(U26,"A") | Z26: =IF(Y26="","",Y26-V26) | AA26: =IF(OR(Y26="",Y26=0),"",V26/Y26) | AB26: =IF(OR(Y26="",Y26=0),"",IF((10-W26-X26)<=0,"N/A",Z26/(10-W26-X26))) | AC26: =IF(W26=0,"",ROUND((V26/W26)*10,0))
A27: Sumeyah Khan | V27: =SUM(B27,D27,F27,H27,J27,L27,N27,P27,R27,T27) | W27: =COUNTIF(C27,"P")+COUNTIF(E27,"P")+COUNTIF(G27,"P")+COUNTIF(I27,"P")+COUNTIF(K27,"P")+COUNTIF(M27,"P")+COUNTIF(O27,"P")+COUNTIF(Q27,"P")+COUNTIF(S27,"P")+COUNTIF(U27,"P") | X27: =COUNTIF(C27,"A")+COUNTIF(E27,"A")+COUNTIF(G27,"A")+COUNTIF(I27,"A")+COUNTIF(K27,"A")+COUNTIF(M27,"A")+COUNTIF(O27,"A")+COUNTIF(Q27,"A")+COUNTIF(S27,"A")+COUNTIF(U27,"A") | Z27: =IF(Y27="","",Y27-V27) | AA27: =IF(OR(Y27="",Y27=0),"",V27/Y27) | AB27: =IF(OR(Y27="",Y27=0),"",IF((10-W27-X27)<=0,"N/A",Z27/(10-W27-X27))) | AC27: =IF(W27=0,"",ROUND((V27/W27)*10,0))
A28: Maria Mujeeb | V28: =SUM(B28,D28,F28,H28,J28,L28,N28,P28,R28,T28) | W28: =COUNTIF(C28,"P")+COUNTIF(E28,"P")+COUNTIF(G28,"P")+COUNTIF(I28,"P")+COUNTIF(K28,"P")+COUNTIF(M28,"P")+COUNTIF(O28,"P")+COUNTIF(Q28,"P")+COUNTIF(S28,"P")+COUNTIF(U28,"P") | X28: =COUNTIF(C28,"A")+COUNTIF(E28,"A")+COUNTIF(G28,"A")+COUNTIF(I28,"A")+COUNTIF(K28,"A")+COUNTIF(M28,"A")+COUNTIF(O28,"A")+COUNTIF(Q28,"A")+COUNTIF(S28,"A")+COUNTIF(U28,"A") | Z28: =IF(Y28="","",Y28-V28) | AA28: =IF(OR(Y28="",Y28=0),"",V28/Y28) | AB28: =IF(OR(Y28="",Y28=0),"",IF((10-W28-X28)<=0,"N/A",Z28/(10-W28-X28))) | AC28: =IF(W28=0,"",ROUND((V28/W28)*10,0))
A29: Jace Ratliff | V29: =SUM(B29,D29,F29,H29,J29,L29,N29,P29,R29,T29) | W29: =COUNTIF(C29,"P")+COUNTIF(E29,"P")+COUNTIF(G29,"P")+COUNTIF(I29,"P")+COUNTIF(K29,"P")+COUNTIF(M29,"P")+COUNTIF(O29,"P")+COUNTIF(Q29,"P")+COUNTIF(S29,"P")+COUNTIF(U29,"P") | X29: =COUNTIF(C29,"A")+COUNTIF(E29,"A")+COUNTIF(G29,"A")+COUNTIF(I29,"A")+COUNTIF(K29,"A")+COUNTIF(M29,"A")+COUNTIF(O29,"A")+COUNTIF(Q29,"A")+COUNTIF(S29,"A")+COUNTIF(U29,"A") | Z29: =IF(Y29="","",Y29-V29) | AA29: =IF(OR(Y29="",Y29=0),"",V29/Y29) | AB29: =IF(OR(Y29="",Y29=0),"",IF((10-W29-X29)<=0,"N/A",Z29/(10-W29-X29))) | AC29: =IF(W29=0,"",ROUND((V29/W29)*10,0))
A30: Evan Allen | V30: =SUM(B30,D30,F30,H30,J30,L30,N30,P30,R30,T30) | W30: =COUNTIF(C30,"P")+COUNTIF(E30,"P")+COUNTIF(G30,"P")+COUNTIF(I30,"P")+COUNTIF(K30,"P")+COUNTIF(M30,"P")+COUNTIF(O30,"P")+COUNTIF(Q30,"P")+COUNTIF(S30,"P")+COUNTIF(U30,"P") | X30: =COUNTIF(C30,"A")+COUNTIF(E30,"A")+COUNTIF(G30,"A")+COUNTIF(I30,"A")+COUNTIF(K30,"A")+COUNTIF(M30,"A")+COUNTIF(O30,"A")+COUNTIF(Q30,"A")+COUNTIF(S30,"A")+COUNTIF(U30,"A") | Z30: =IF(Y30="","",Y30-V30) | AA30: =IF(OR(Y30="",Y30=0),"",V30/Y30) | AB30: =IF(OR(Y30="",Y30=0),"",IF((10-W30-X30)<=0,"N/A",Z30/(10-W30-X30))) | AC30: =IF(W30=0,"",ROUND((V30/W30)*10,0))
A31: Sai Neelagiri | V31: =SUM(B31,D31,F31,H31,J31,L31,N31,P31,R31,T31) | W31: =COUNTIF(C31,"P")+COUNTIF(E31,"P")+COUNTIF(G31,"P")+COUNTIF(I31,"P")+COUNTIF(K31,"P")+COUNTIF(M31,"P")+COUNTIF(O31,"P")+COUNTIF(Q31,"P")+COUNTIF(S31,"P")+COUNTIF(U31,"P") | X31: =COUNTIF(C31,"A")+COUNTIF(E31,"A")+COUNTIF(G31,"A")+COUNTIF(I31,"A")+COUNTIF(K31,"A")+COUNTIF(M31,"A")+COUNTIF(O31,"A")+COUNTIF(Q31,"A")+COUNTIF(S31,"A")+COUNTIF(U31,"A") | Z31: =IF(Y31="","",Y31-V31) | AA31: =IF(OR(Y31="",Y31=0),"",V31/Y31) | AB31: =IF(OR(Y31="",Y31=0),"",IF((10-W31-X31)<=0,"N/A",Z31/(10-W31-X31))) | AC31: =IF(W31=0,"",ROUND((V31/W31)*10,0))
A32: Fletcher Meese | V32: =SUM(B32,D32,F32,H32,J32,L32,N32,P32,R32,T32) | W32: =COUNTIF(C32,"P")+COUNTIF(E32,"P")+COUNTIF(G32,"P")+COUNTIF(I32,"P")+COUNTIF(K32,"P")+COUNTIF(M32,"P")+COUNTIF(O32,"P")+COUNTIF(Q32,"P")+COUNTIF(S32,"P")+COUNTIF(U32,"P") | X32: =COUNTIF(C32,"A")+COUNTIF(E32,"A")+COUNTIF(G32,"A")+COUNTIF(I32,"A")+COUNTIF(K32,"A")+COUNTIF(M32,"A")+COUNTIF(O32,"A")+COUNTIF(Q32,"A")+COUNTIF(S32,"A")+COUNTIF(U32,"A") | Z32: =IF(Y32="","",Y32-V32) | AA32: =IF(OR(Y32="",Y32=0),"",V32/Y32) | AB32: =IF(OR(Y32="",Y32=0),"",IF((10-W32-X32)<=0,"N/A",Z32/(10-W32-X32))) | AC32: =IF(W32=0,"",ROUND((V32/W32)*10,0))
A33: Elijah Aldaco | V33: =SUM(B33,D33,F33,H33,J33,L33,N33,P33,R33,T33) | W33: =COUNTIF(C33,"P")+COUNTIF(E33,"P")+COUNTIF(G33,"P")+COUNTIF(I33,"P")+COUNTIF(K33,"P")+COUNTIF(M33,"P")+COUNTIF(O33,"P")+COUNTIF(Q33,"P")+COUNTIF(S33,"P")+COUNTIF(U33,"P") | X33: =COUNTIF(C33,"A")+COUNTIF(E33,"A")+COUNTIF(G33,"A")+COUNTIF(I33,"A")+COUNTIF(K33,"A")+COUNTIF(M33,"A")+COUNTIF(O33,"A")+COUNTIF(Q33,"A")+COUNTIF(S33,"A")+COUNTIF(U33,"A") | Z33: =IF(Y33="","",Y33-V33) | AA33: =IF(OR(Y33="",Y33=0),"",V33/Y33) | AB33: =IF(OR(Y33="",Y33=0),"",IF((10-W33-X33)<=0,"N/A",Z33/(10-W33-X33))) | AC33: =IF(W33=0,"",ROUND((V33/W33)*10,0))
A34: Cain Gutierrez | V34: =SUM(B34,D34,F34,H34,J34,L34,N34,P34,R34,T34) | W34: =COUNTIF(C34,"P")+COUNTIF(E34,"P")+COUNTIF(G34,"P")+COUNTIF(I34,"P")+COUNTIF(K34,"P")+COUNTIF(M34,"P")+COUNTIF(O34,"P")+COUNTIF(Q34,"P")+COUNTIF(S34,"P")+COUNTIF(U34,"P") | X34: =COUNTIF(C34,"A")+COUNTIF(E34,"A")+COUNTIF(G34,"A")+COUNTIF(I34,"A")+COUNTIF(K34,"A")+COUNTIF(M34,"A")+COUNTIF(O34,"A")+COUNTIF(Q34,"A")+COUNTIF(S34,"A")+COUNTIF(U34,"A") | Z34: =IF(Y34="","",Y34-V34) | AA34: =IF(OR(Y34="",Y34=0),"",V34/Y34) | AB34: =IF(OR(Y34="",Y34=0),"",IF((10-W34-X34)<=0,"N/A",Z34/(10-W34-X34))) | AC34: =IF(W34=0,"",ROUND((V34/W34)*10,0))
A35: Grayson Barnhart | V35: =SUM(B35,D35,F35,H35,J35,L35,N35,P35,R35,T35) | W35: =COUNTIF(C35,"P")+COUNTIF(E35,"P")+COUNTIF(G35,"P")+COUNTIF(I35,"P")+COUNTIF(K35,"P")+COUNTIF(M35,"P")+COUNTIF(O35,"P")+COUNTIF(Q35,"P")+COUNTIF(S35,"P")+COUNTIF(U35,"P") | X35: =COUNTIF(C35,"A")+COUNTIF(E35,"A")+COUNTIF(G35,"A")+COUNTIF(I35,"A")+COUNTIF(K35,"A")+COUNTIF(M35,"A")+COUNTIF(O35,"A")+COUNTIF(Q35,"A")+COUNTIF(S35,"A")+COUNTIF(U35,"A") | Z35: =IF(Y35="","",Y35-V35) | AA35: =IF(OR(Y35="",Y35=0),"",V35/Y35) | AB35: =IF(OR(Y35="",Y35=0),"",IF((10-W35-X35)<=0,"N/A",Z35/(10-W35-X35))) | AC35: =IF(W35=0,"",ROUND((V35/W35)*10,0))
... A38: Jason Bean | V38: =SUM(B38,D38,F38,H38,J38,L38,N38,P38,R38,T38) | W38: =COUNTIF(C38,"P")+COUNTIF(E38,"P")+COUNTIF(G38,"P")+COUNTIF(I38,"P")+COUNTIF(K38,"P")+COUNTIF(M38,"P")+COUNTIF(O38,"P")+COUNTIF(Q38,"P")+COUNTIF(S38,"P")+COUNTIF(U38,"P") | X38: =COUNTIF(C38,"A")+COUNTIF(E38,"A")+COUNTIF(G38,"A")+COUNTIF(I38,"A")+COUNTIF(K38,"A")+COUNTIF(M38,"A")+COUNTIF(O38,"A")+COUNTIF(Q38,"A")+COUNTIF(S38,"A")+COUNTIF(U38,"A") | Z38: =IF(Y38="","",Y38-V38) | AA38: =IF(OR(Y38="",Y38=0),"",V38/Y38) | AB38: =IF(OR(Y38="",Y38=0),"",IF((10-W38-X38)<=0,"N/A",Z38/(10-W38-X38))) | AC38: =IF(W38=0,"",ROUND((V38/W38)*10,0))
A41: Q3 — Quarter 3
A42: Student Name | B42: Sess 1 | C42: Att 1 | D42: Sess 2 | E42: Att 2 | F42: Sess 3 | G42: Att 3 | H42: Sess 4 | I42: Att 4 | J42: Sess 5 | K42: Att 5 | L42: Sess 6 | M42: Att 6 | N42: Sess 7 | O42: Att 7 | P42: Sess 8 | Q42: Att 8 | R42: Sess 9 | S42: Att 9 | T42: Sess 10 | U42: Att 10 | V42: Min Met | W42: Sess Att | X42: Absences | Y42: IEP Req | Z42: Min Remain | AA42: % Complete | AB42: Pace Needed | AC42: Projected
A43: Raya Hightower | V43: =SUM(B43,D43,F43,H43,J43,L43,N43,P43,R43,T43) | W43: =COUNTIF(C43,"P")+COUNTIF(E43,"P")+COUNTIF(G43,"P")+COUNTIF(I43,"P")+COUNTIF(K43,"P")+COUNTIF(M43,"P")+COUNTIF(O43,"P")+COUNTIF(Q43,"P")+COUNTIF(S43,"P")+COUNTIF(U43,"P") | X43: =COUNTIF(C43,"A")+COUNTIF(E43,"A")+COUNTIF(G43,"A")+COUNTIF(I43,"A")+COUNTIF(K43,"A")+COUNTIF(M43,"A")+COUNTIF(O43,"A")+COUNTIF(Q43,"A")+COUNTIF(S43,"A")+COUNTIF(U43,"A") | Z43: =IF(Y43="","",Y43-V43) | AA43: =IF(OR(Y43="",Y43=0),"",V43/Y43) | AB43: =IF(OR(Y43="",Y43=0),"",IF((10-W43-X43)<=0,"N/A",Z43/(10-W43-X43))) | AC43: =IF(W43=0,"",ROUND((V43/W43)*10,0))
A44: Anu Vijay Anand | V44: =SUM(B44,D44,F44,H44,J44,L44,N44,P44,R44,T44) | W44: =COUNTIF(C44,"P")+COUNTIF(E44,"P")+COUNTIF(G44,"P")+COUNTIF(I44,"P")+COUNTIF(K44,"P")+COUNTIF(M44,"P")+COUNTIF(O44,"P")+COUNTIF(Q44,"P")+COUNTIF(S44,"P")+COUNTIF(U44,"P") | X44: =COUNTIF(C44,"A")+COUNTIF(E44,"A")+COUNTIF(G44,"A")+COUNTIF(I44,"A")+COUNTIF(K44,"A")+COUNTIF(M44,"A")+COUNTIF(O44,"A")+COUNTIF(Q44,"A")+COUNTIF(S44,"A")+COUNTIF(U44,"A") | Z44: =IF(Y44="","",Y44-V44) | AA44: =IF(OR(Y44="",Y44=0),"",V44/Y44) | AB44: =IF(OR(Y44="",Y44=0),"",IF((10-W44-X44)<=0,"N/A",Z44/(10-W44-X44))) | AC44: =IF(W44=0,"",ROUND((V44/W44)*10,0))
A45: Aadhya Gone | V45: =SUM(B45,D45,F45,H45,J45,L45,N45,P45,R45,T45) | W45: =COUNTIF(C45,"P")+COUNTIF(E45,"P")+COUNTIF(G45,"P")+COUNTIF(I45,"P")+COUNTIF(K45,"P")+COUNTIF(M45,"P")+COUNTIF(O45,"P")+COUNTIF(Q45,"P")+COUNTIF(S45,"P")+COUNTIF(U45,"P") | X45: =COUNTIF(C45,"A")+COUNTIF(E45,"A")+COUNTIF(G45,"A")+COUNTIF(I45,"A")+COUNTIF(K45,"A")+COUNTIF(M45,"A")+COUNTIF(O45,"A")+COUNTIF(Q45,"A")+COUNTIF(S45,"A")+COUNTIF(U45,"A") | Z45: =IF(Y45="","",Y45-V45) | AA45: =IF(OR(Y45="",Y45=0),"",V45/Y45) | AB45: =IF(OR(Y45="",Y45=0),"",IF((10-W45-X45)<=0,"N/A",Z45/(10-W45-X45))) | AC45: =IF(W45=0,"",ROUND((V45/W45)*10,0))
A46: Sumeyah Khan | V46: =SUM(B46,D46,F46,H46,J46,L46,N46,P46,R46,T46) | W46: =COUNTIF(C46,"P")+COUNTIF(E46,"P")+COUNTIF(G46,"P")+COUNTIF(I46,"P")+COUNTIF(K46,"P")+COUNTIF(M46,"P")+COUNTIF(O46,"P")+COUNTIF(Q46,"P")+COUNTIF(S46,"P")+COUNTIF(U46,"P") | X46: =COUNTIF(C46,"A")+COUNTIF(E46,"A")+COUNTIF(G46,"A")+COUNTIF(I46,"A")+COUNTIF(K46,"A")+COUNTIF(M46,"A")+COUNTIF(O46,"A")+COUNTIF(Q46,"A")+COUNTIF(S46,"A")+COUNTIF(U46,"A") | Z46: =IF(Y46="","",Y46-V46) | AA46: =IF(OR(Y46="",Y46=0),"",V46/Y46) | AB46: =IF(OR(Y46="",Y46=0),"",IF((10-W46-X46)<=0,"N/A",Z46/(10-W46-X46))) | AC46: =IF(W46=0,"",ROUND((V46/W46)*10,0))
A47: Maria Mujeeb | V47: =SUM(B47,D47,F47,H47,J47,L47,N47,P47,R47,T47) | W47: =COUNTIF(C47,"P")+COUNTIF(E47,"P")+COUNTIF(G47,"P")+COUNTIF(I47,"P")+COUNTIF(K47,"P")+COUNTIF(M47,"P")+COUNTIF(O47,"P")+COUNTIF(Q47,"P")+COUNTIF(S47,"P")+COUNTIF(U47,"P") | X47: =COUNTIF(C47,"A")+COUNTIF(E47,"A")+COUNTIF(G47,"A")+COUNTIF(I47,"A")+COUNTIF(K47,"A")+COUNTIF(M47,"A")+COUNTIF(O47,"A")+COUNTIF(Q47,"A")+COUNTIF(S47,"A")+COUNTIF(U47,"A") | Z47: =IF(Y47="","",Y47-V47) | AA47: =IF(OR(Y47="",Y47=0),"",V47/Y47) | AB47: =IF(OR(Y47="",Y47=0),"",IF((10-W47-X47)<=0,"N/A",Z47/(10-W47-X47))) | AC47: =IF(W47=0,"",ROUND((V47/W47)*10,0))
A48: Jace Ratliff | V48: =SUM(B48,D48,F48,H48,J48,L48,N48,P48,R48,T48) | W48: =COUNTIF(C48,"P")+COUNTIF(E48,"P")+COUNTIF(G48,"P")+COUNTIF(I48,"P")+COUNTIF(K48,"P")+COUNTIF(M48,"P")+COUNTIF(O48,"P")+COUNTIF(Q48,"P")+COUNTIF(S48,"P")+COUNTIF(U48,"P") | X48: =COUNTIF(C48,"A")+COUNTIF(E48,"A")+COUNTIF(G48,"A")+COUNTIF(I48,"A")+COUNTIF(K48,"A")+COUNTIF(M48,"A")+COUNTIF(O48,"A")+COUNTIF(Q48,"A")+COUNTIF(S48,"A")+COUNTIF(U48,"A") | Z48: =IF(Y48="","",Y48-V48) | AA48: =IF(OR(Y48="",Y48=0),"",V48/Y48) | AB48: =IF(OR(Y48="",Y48=0),"",IF((10-W48-X48)<=0,"N/A",Z48/(10-W48-X48))) | AC48: =IF(W48=0,"",ROUND((V48/W48)*10,0))
A49: Evan Allen | V49: =SUM(B49,D49,F49,H49,J49,L49,N49,P49,R49,T49) | W49: =COUNTIF(C49,"P")+COUNTIF(E49,"P")+COUNTIF(G49,"P")+COUNTIF(I49,"P")+COUNTIF(K49,"P")+COUNTIF(M49,"P")+COUNTIF(O49,"P")+COUNTIF(Q49,"P")+COUNTIF(S49,"P")+COUNTIF(U49,"P") | X49: =COUNTIF(C49,"A")+COUNTIF(E49,"A")+COUNTIF(G49,"A")+COUNTIF(I49,"A")+COUNTIF(K49,"A")+COUNTIF(M49,"A")+COUNTIF(O49,"A")+COUNTIF(Q49,"A")+COUNTIF(S49,"A")+COUNTIF(U49,"A") | Z49: =IF(Y49="","",Y49-V49) | AA49: =IF(OR(Y49="",Y49=0),"",V49/Y49) | AB49: =IF(OR(Y49="",Y49=0),"",IF((10-W49-X49)<=0,"N/A",Z49/(10-W49-X49))) | AC49: =IF(W49=0,"",ROUND((V49/W49)*10,0))
...

Sheet OT
A1: OT — SPED Minute Tracker
A3: Q1 — Quarter 1
A4: Student Name | B4: Sess 1 | C4: Att 1 | D4: Sess 2 | E4: Att 2 | F4: Sess 3 | G4: Att 3 | H4: Sess 4 | I4: Att 4 | J4: Sess 5 | K4: Att 5 | L4: Sess 6 | M4: Att 6 | N4: Sess 7 | O4: Att 7 | P4: Sess 8 | Q4: Att 8 | R4: Sess 9 | S4: Att 9 | T4: Sess 10 | U4: Att 10 | V4: Min Met | W4: Sess Att | X4: Absences | Y4: IEP Req | Z4: Min Remain | AA4: % Complete | AB4: Pace Needed | AC4: Projected
A5: Raya Hightower | V5: =SUM(B5,D5,F5,H5,J5,L5,N5,P5,R5,T5) | W5: =COUNTIF(C5,"P")+COUNTIF(E5,"P")+COUNTIF(G5,"P")+COUNTIF(I5,"P")+COUNTIF(K5,"P")+COUNTIF(M5,"P")+COUNTIF(O5,"P")+COUNTIF(Q5,"P")+COUNTIF(S5,"P")+COUNTIF(U5,"P") | X5: =COUNTIF(C5,"A")+COUNTIF(E5,"A")+COUNTIF(G5,"A")+COUNTIF(I5,"A")+COUNTIF(K5,"A")+COUNTIF(M5,"A")+COUNTIF(O5,"A")+COUNTIF(Q5,"A")+COUNTIF(S5,"A")+COUNTIF(U5,"A") | Z5: =IF(Y5="","",Y5-V5) | AA5: =IF(OR(Y5="",Y5=0),"",V5/Y5) | AB5: =IF(OR(Y5="",Y5=0),"",IF((10-W5-X5)<=0,"N/A",Z5/(10-W5-X5))) | AC5: =IF(W5=0,"",ROUND((V5/W5)*10,0))
A6: Anu Vijay Anand | V6: =SUM(B6,D6,F6,H6,J6,L6,N6,P6,R6,T6) | W6: =COUNTIF(C6,"P")+COUNTIF(E6,"P")+COUNTIF(G6,"P")+COUNTIF(I6,"P")+COUNTIF(K6,"P")+COUNTIF(M6,"P")+COUNTIF(O6,"P")+COUNTIF(Q6,"P")+COUNTIF(S6,"P")+COUNTIF(U6,"P") | X6: =COUNTIF(C6,"A")+COUNTIF(E6,"A")+COUNTIF(G6,"A")+COUNTIF(I6,"A")+COUNTIF(K6,"A")+COUNTIF(M6,"A")+COUNTIF(O6,"A")+COUNTIF(Q6,"A")+COUNTIF(S6,"A")+COUNTIF(U6,"A") | Z6: =IF(Y6="","",Y6-V6) | AA6: =IF(OR(Y6="",Y6=0),"",V6/Y6) | AB6: =IF(OR(Y6="",Y6=0),"",IF((10-W6-X6)<=0,"N/A",Z6/(10-W6-X6))) | AC6: =IF(W6=0,"",ROUND((V6/W6)*10,0))
A7: Aadhya Gone | V7: =SUM(B7,D7,F7,H7,J7,L7,N7,P7,R7,T7) | W7: =COUNTIF(C7,"P")+COUNTIF(E7,"P")+COUNTIF(G7,"P")+COUNTIF(I7,"P")+COUNTIF(K7,"P")+COUNTIF(M7,"P")+COUNTIF(O7,"P")+COUNTIF(Q7,"P")+COUNTIF(S7,"P")+COUNTIF(U7,"P") | X7: =COUNTIF(C7,"A")+COUNTIF(E7,"A")+COUNTIF(G7,"A")+COUNTIF(I7,"A")+COUNTIF(K7,"A")+COUNTIF(M7,"A")+COUNTIF(O7,"A")+COUNTIF(Q7,"A")+COUNTIF(S7,"A")+COUNTIF(U7,"A") | Z7: =IF(Y7="","",Y7-V7) | AA7: =IF(OR(Y7="",Y7=0),"",V7/Y7) | AB7: =IF(OR(Y7="",Y7=0),"",IF((10-W7-X7)<=0,"N/A",Z7/(10-W7-X7))) | AC7: =IF(W7=0,"",ROUND((V7/W7)*10,0))
A8: Sumeyah Khan | V8: =SUM(B8,D8,F8,H8,J8,L8,N8,P8,R8,T8) | W8: =COUNTIF(C8,"P")+COUNTIF(E8,"P")+COUNTIF(G8,"P")+COUNTIF(I8,"P")+COUNTIF(K8,"P")+COUNTIF(M8,"P")+COUNTIF(O8,"P")+COUNTIF(Q8,"P")+COUNTIF(S8,"P")+COUNTIF(U8,"P") | X8: =COUNTIF(C8,"A")+COUNTIF(E8,"A")+COUNTIF(G8,"A")+COUNTIF(I8,"A")+COUNTIF(K8,"A")+COUNTIF(M8,"A")+COUNTIF(O8,"A")+COUNTIF(Q8,"A")+COUNTIF(S8,"A")+COUNTIF(U8,"A") | Z8: =IF(Y8="","",Y8-V8) | AA8: =IF(OR(Y8="",Y8=0),"",V8/Y8) | AB8: =IF(OR(Y8="",Y8=0),"",IF((10-W8-X8)<=0,"N/A",Z8/(10-W8-X8))) | AC8: =IF(W8=0,"",ROUND((V8/W8)*10,0))
A9: Maria Mujeeb | V9: =SUM(B9,D9,F9,H9,J9,L9,N9,P9,R9,T9) | W9: =COUNTIF(C9,"P")+COUNTIF(E9,"P")+COUNTIF(G9,"P")+COUNTIF(I9,"P")+COUNTIF(K9,"P")+COUNTIF(M9,"P")+COUNTIF(O9,"P")+COUNTIF(Q9,"P")+COUNTIF(S9,"P")+COUNTIF(U9,"P") | X9: =COUNTIF(C9,"A")+COUNTIF(E9,"A")+COUNTIF(G9,"A")+COUNTIF(I9,"A")+COUNTIF(K9,"A")+COUNTIF(M9,"A")+COUNTIF(O9,"A")+COUNTIF(Q9,"A")+COUNTIF(S9,"A")+COUNTIF(U9,"A") | Z9: =IF(Y9="","",Y9-V9) | AA9: =IF(OR(Y9="",Y9=0),"",V9/Y9) | AB9: =IF(OR(Y9="",Y9=0),"",IF((10-W9-X9)<=0,"N/A",Z9/(10-W9-X9))) | AC9: =IF(W9=0,"",ROUND((V9/W9)*10,0))
A10: Jace Ratliff | V10: =SUM(B10,D10,F10,H10,J10,L10,N10,P10,R10,T10) | W10: =COUNTIF(C10,"P")+COUNTIF(E10,"P")+COUNTIF(G10,"P")+COUNTIF(I10,"P")+COUNTIF(K10,"P")+COUNTIF(M10,"P")+COUNTIF(O10,"P")+COUNTIF(Q10,"P")+COUNTIF(S10,"P")+COUNTIF(U10,"P") | X10: =COUNTIF(C10,"A")+COUNTIF(E10,"A")+COUNTIF(G10,"A")+COUNTIF(I10,"A")+COUNTIF(K10,"A")+COUNTIF(M10,"A")+COUNTIF(O10,"A")+COUNTIF(Q10,"A")+COUNTIF(S10,"A")+COUNTIF(U10,"A") | Z10: =IF(Y10="","",Y10-V10) | AA10: =IF(OR(Y10="",Y10=0),"",V10/Y10) | AB10: =IF(OR(Y10="",Y10=0),"",IF((10-W10-X10)<=0,"N/A",Z10/(10-W10-X10))) | AC10: =IF(W10=0,"",ROUND((V10/W10)*10,0))
A11: Evan Allen | V11: =SUM(B11,D11,F11,H11,J11,L11,N11,P11,R11,T11) | W11: =COUNTIF(C11,"P")+COUNTIF(E11,"P")+COUNTIF(G11,"P")+COUNTIF(I11,"P")+COUNTIF(K11,"P")+COUNTIF(M11,"P")+COUNTIF(O11,"P")+COUNTIF(Q11,"P")+COUNTIF(S11,"P")+COUNTIF(U11,"P") | X11: =COUNTIF(C11,"A")+COUNTIF(E11,"A")+COUNTIF(G11,"A")+COUNTIF(I11,"A")+COUNTIF(K11,"A")+COUNTIF(M11,"A")+COUNTIF(O11,"A")+COUNTIF(Q11,"A")+COUNTIF(S11,"A")+COUNTIF(U11,"A") | Z11: =IF(Y11="","",Y11-V11) | AA11: =IF(OR(Y11="",Y11=0),"",V11/Y11) | AB11: =IF(OR(Y11="",Y11=0),"",IF((10-W11-X11)<=0,"N/A",Z11/(10-W11-X11))) | AC11: =IF(W11=0,"",ROUND((V11/W11)*10,0))
A12: Sai Neelagiri | V12: =SUM(B12,D12,F12,H12,J12,L12,N12,P12,R12,T12) | W12: =COUNTIF(C12,"P")+COUNTIF(E12,"P")+COUNTIF(G12,"P")+COUNTIF(I12,"P")+COUNTIF(K12,"P")+COUNTIF(M12,"P")+COUNTIF(O12,"P")+COUNTIF(Q12,"P")+COUNTIF(S12,"P")+COUNTIF(U12,"P") | X12: =COUNTIF(C12,"A")+COUNTIF(E12,"A")+COUNTIF(G12,"A")+COUNTIF(I12,"A")+COUNTIF(K12,"A")+COUNTIF(M12,"A")+COUNTIF(O12,"A")+COUNTIF(Q12,"A")+COUNTIF(S12,"A")+COUNTIF(U12,"A") | Z12: =IF(Y12="","",Y12-V12) | AA12: =IF(OR(Y12="",Y12=0),"",V12/Y12) | AB12: =IF(OR(Y12="",Y12=0),"",IF((10-W12-X12)<=0,"N/A",Z12/(10-W12-X12))) | AC12: =IF(W12=0,"",ROUND((V12/W12)*10,0))
A13: Fletcher Meese | V13: =SUM(B13,D13,F13,H13,J13,L13,N13,P13,R13,T13) | W13: =COUNTIF(C13,"P")+COUNTIF(E13,"P")+COUNTIF(G13,"P")+COUNTIF(I13,"P")+COUNTIF(K13,"P")+COUNTIF(M13,"P")+COUNTIF(O13,"P")+COUNTIF(Q13,"P")+COUNTIF(S13,"P")+COUNTIF(U13,"P") | X13: =COUNTIF(C13,"A")+COUNTIF(E13,"A")+COUNTIF(G13,"A")+COUNTIF(I13,"A")+COUNTIF(K13,"A")+COUNTIF(M13,"A")+COUNTIF(O13,"A")+COUNTIF(Q13,"A")+COUNTIF(S13,"A")+COUNTIF(U13,"A") | Z13: =IF(Y13="","",Y13-V13) | AA13: =IF(OR(Y13="",Y13=0),"",V13/Y13) | AB13: =IF(OR(Y13="",Y13=0),"",IF((10-W13-X13)<=0,"N/A",Z13/(10-W13-X13))) | AC13: =IF(W13=0,"",ROUND((V13/W13)*10,0))
A14: Elijah Aldaco | V14: =SUM(B14,D14,F14,H14,J14,L14,N14,P14,R14,T14) | W14: =COUNTIF(C14,"P")+COUNTIF(E14,"P")+COUNTIF(G14,"P")+COUNTIF(I14,"P")+COUNTIF(K14,"P")+COUNTIF(M14,"P")+COUNTIF(O14,"P")+COUNTIF(Q14,"P")+COUNTIF(S14,"P")+COUNTIF(U14,"P") | X14: =COUNTIF(C14,"A")+COUNTIF(E14,"A")+COUNTIF(G14,"A")+COUNTIF(I14,"A")+COUNTIF(K14,"A")+COUNTIF(M14,"A")+COUNTIF(O14,"A")+COUNTIF(Q14,"A")+COUNTIF(S14,"A")+COUNTIF(U14,"A") | Z14: =IF(Y14="","",Y14-V14) | AA14: =IF(OR(Y14="",Y14=0),"",V14/Y14) | AB14: =IF(OR(Y14="",Y14=0),"",IF((10-W14-X14)<=0,"N/A",Z14/(10-W14-X14))) | AC14: =IF(W14=0,"",ROUND((V14/W14)*10,0))
A15: Cain Gutierrez | V15: =SUM(B15,D15,F15,H15,J15,L15,N15,P15,R15,T15) | W15: =COUNTIF(C15,"P")+COUNTIF(E15,"P")+COUNTIF(G15,"P")+COUNTIF(I15,"P")+COUNTIF(K15,"P")+COUNTIF(M15,"P")+COUNTIF(O15,"P")+COUNTIF(Q15,"P")+COUNTIF(S15,"P")+COUNTIF(U15,"P") | X15: =COUNTIF(C15,"A")+COUNTIF(E15,"A")+COUNTIF(G15,"A")+COUNTIF(I15,"A")+COUNTIF(K15,"A")+COUNTIF(M15,"A")+COUNTIF(O15,"A")+COUNTIF(Q15,"A")+COUNTIF(S15,"A")+COUNTIF(U15,"A") | Z15: =IF(Y15="","",Y15-V15) | AA15: =IF(OR(Y15="",Y15=0),"",V15/Y15) | AB15: =IF(OR(Y15="",Y15=0),"",IF((10-W15-X15)<=0,"N/A",Z15/(10-W15-X15))) | AC15: =IF(W15=0,"",ROUND((V15/W15)*10,0))
A16: Grayson Barnhart | V16: =SUM(B16,D16,F16,H16,J16,L16,N16,P16,R16,T16) | W16: =COUNTIF(C16,"P")+COUNTIF(E16,"P")+COUNTIF(G16,"P")+COUNTIF(I16,"P")+COUNTIF(K16,"P")+COUNTIF(M16,"P")+COUNTIF(O16,"P")+COUNTIF(Q16,"P")+COUNTIF(S16,"P")+COUNTIF(U16,"P") | X16: =COUNTIF(C16,"A")+COUNTIF(E16,"A")+COUNTIF(G16,"A")+COUNTIF(I16,"A")+COUNTIF(K16,"A")+COUNTIF(M16,"A")+COUNTIF(O16,"A")+COUNTIF(Q16,"A")+COUNTIF(S16,"A")+COUNTIF(U16,"A") | Z16: =IF(Y16="","",Y16-V16) | AA16: =IF(OR(Y16="",Y16=0),"",V16/Y16) | AB16: =IF(OR(Y16="",Y16=0),"",IF((10-W16-X16)<=0,"N/A",Z16/(10-W16-X16))) | AC16: =IF(W16=0,"",ROUND((V16/W16)*10,0))
... A19: Jason Bean | V19: =SUM(B19,D19,F19,H19,J19,L19,N19,P19,R19,T19) | W19: =COUNTIF(C19,"P")+COUNTIF(E19,"P")+COUNTIF(G19,"P")+COUNTIF(I19,"P")+COUNTIF(K19,"P")+COUNTIF(M19,"P")+COUNTIF(O19,"P")+COUNTIF(Q19,"P")+COUNTIF(S19,"P")+COUNTIF(U19,"P") | X19: =COUNTIF(C19,"A")+COUNTIF(E19,"A")+COUNTIF(G19,"A")+COUNTIF(I19,"A")+COUNTIF(K19,"A")+COUNTIF(M19,"A")+COUNTIF(O19,"A")+COUNTIF(Q19,"A")+COUNTIF(S19,"A")+COUNTIF(U19,"A") | Z19: =IF(Y19="","",Y19-V19) | AA19: =IF(OR(Y19="",Y19=0),"",V19/Y19) | AB19: =IF(OR(Y19="",Y19=0),"",IF((10-W19-X19)<=0,"N/A",Z19/(10-W19-X19))) | AC19: =IF(W19=0,"",ROUND((V19/W19)*10,0))
A22: Q2 — Quarter 2
A23: Student Name | B23: Sess 1 | C23: Att 1 | D23: Sess 2 | E23: Att 2 | F23: Sess 3 | G23: Att 3 | H23: Sess 4 | I23: Att 4 | J23: Sess 5 | K23: Att 5 | L23: Sess 6 | M23: Att 6 | N23: Sess 7 | O23: Att 7 | P23: Sess 8 | Q23: Att 8 | R23: Sess 9 | S23: Att 9 | T23: Sess 10 | U23: Att 10 | V23: Min Met | W23: Sess Att | X23: Absences | Y23: IEP Req | Z23: Min Remain | AA23: % Complete | AB23: Pace Needed | AC23: Projected
A24: Raya Hightower | V24: =SUM(B24,D24,F24,H24,J24,L24,N24,P24,R24,T24) | W24: =COUNTIF(C24,"P")+COUNTIF(E24,"P")+COUNTIF(G24,"P")+COUNTIF(I24,"P")+COUNTIF(K24,"P")+COUNTIF(M24,"P")+COUNTIF(O24,"P")+COUNTIF(Q24,"P")+COUNTIF(S24,"P")+COUNTIF(U24,"P") | X24: =COUNTIF(C24,"A")+COUNTIF(E24,"A")+COUNTIF(G24,"A")+COUNTIF(I24,"A")+COUNTIF(K24,"A")+COUNTIF(M24,"A")+COUNTIF(O24,"A")+COUNTIF(Q24,"A")+COUNTIF(S24,"A")+COUNTIF(U24,"A") | Z24: =IF(Y24="","",Y24-V24) | AA24: =IF(OR(Y24="",Y24=0),"",V24/Y24) | AB24: =IF(OR(Y24="",Y24=0),"",IF((10-W24-X24)<=0,"N/A",Z24/(10-W24-X24))) | AC24: =IF(W24=0,"",ROUND((V24/W24)*10,0))
A25: Anu Vijay Anand | V25: =SUM(B25,D25,F25,H25,J25,L25,N25,P25,R25,T25) | W25: =COUNTIF(C25,"P")+COUNTIF(E25,"P")+COUNTIF(G25,"P")+COUNTIF(I25,"P")+COUNTIF(K25,"P")+COUNTIF(M25,"P")+COUNTIF(O25,"P")+COUNTIF(Q25,"P")+COUNTIF(S25,"P")+COUNTIF(U25,"P") | X25: =COUNTIF(C25,"A")+COUNTIF(E25,"A")+COUNTIF(G25,"A")+COUNTIF(I25,"A")+COUNTIF(K25,"A")+COUNTIF(M25,"A")+COUNTIF(O25,"A")+COUNTIF(Q25,"A")+COUNTIF(S25,"A")+COUNTIF(U25,"A") | Z25: =IF(Y25="","",Y25-V25) | AA25: =IF(OR(Y25="",Y25=0),"",V25/Y25) | AB25: =IF(OR(Y25="",Y25=0),"",IF((10-W25-X25)<=0,"N/A",Z25/(10-W25-X25))) | AC25: =IF(W25=0,"",ROUND((V25/W25)*10,0))
A26: Aadhya Gone | V26: =SUM(B26,D26,F26,H26,J26,L26,N26,P26,R26,T26) | W26: =COUNTIF(C26,"P")+COUNTIF(E26,"P")+COUNTIF(G26,"P")+COUNTIF(I26,"P")+COUNTIF(K26,"P")+COUNTIF(M26,"P")+COUNTIF(O26,"P")+COUNTIF(Q26,"P")+COUNTIF(S26,"P")+COUNTIF(U26,"P") | X26: =COUNTIF(C26,"A")+COUNTIF(E26,"A")+COUNTIF(G26,"A")+COUNTIF(I26,"A")+COUNTIF(K26,"A")+COUNTIF(M26,"A")+COUNTIF(O26,"A")+COUNTIF(Q26,"A")+COUNTIF(S26,"A")+COUNTIF(U26,"A") | Z26: =IF(Y26="","",Y26-V26) | AA26: =IF(OR(Y26="",Y26=0),"",V26/Y26) | AB26: =IF(OR(Y26="",Y26=0),"",IF((10-W26-X26)<=0,"N/A",Z26/(10-W26-X26))) | AC26: =IF(W26=0,"",ROUND((V26/W26)*10,0))
A27: Sumeyah Khan | V27: =SUM(B27,D27,F27,H27,J27,L27,N27,P27,R27,T27) | W27: =COUNTIF(C27,"P")+COUNTIF(E27,"P")+COUNTIF(G27,"P")+COUNTIF(I27,"P")+COUNTIF(K27,"P")+COUNTIF(M27,"P")+COUNTIF(O27,"P")+COUNTIF(Q27,"P")+COUNTIF(S27,"P")+COUNTIF(U27,"P") | X27: =COUNTIF(C27,"A")+COUNTIF(E27,"A")+COUNTIF(G27,"A")+COUNTIF(I27,"A")+COUNTIF(K27,"A")+COUNTIF(M27,"A")+COUNTIF(O27,"A")+COUNTIF(Q27,"A")+COUNTIF(S27,"A")+COUNTIF(U27,"A") | Z27: =IF(Y27="","",Y27-V27) | AA27: =IF(OR(Y27="",Y27=0),"",V27/Y27) | AB27: =IF(OR(Y27="",Y27=0),"",IF((10-W27-X27)<=0,"N/A",Z27/(10-W27-X27))) | AC27: =IF(W27=0,"",ROUND((V27/W27)*10,0))
A28: Maria Mujeeb | V28: =SUM(B28,D28,F28,H28,J28,L28,N28,P28,R28,T28) | W28: =COUNTIF(C28,"P")+COUNTIF(E28,"P")+COUNTIF(G28,"P")+COUNTIF(I28,"P")+COUNTIF(K28,"P")+COUNTIF(M28,"P")+COUNTIF(O28,"P")+COUNTIF(Q28,"P")+COUNTIF(S28,"P")+COUNTIF(U28,"P") | X28: =COUNTIF(C28,"A")+COUNTIF(E28,"A")+COUNTIF(G28,"A")+COUNTIF(I28,"A")+COUNTIF(K28,"A")+COUNTIF(M28,"A")+COUNTIF(O28,"A")+COUNTIF(Q28,"A")+COUNTIF(S28,"A")+COUNTIF(U28,"A") | Z28: =IF(Y28="","",Y28-V28) | AA28: =IF(OR(Y28="",Y28=0),"",V28/Y28) | AB28: =IF(OR(Y28="",Y28=0),"",IF((10-W28-X28)<=0,"N/A",Z28/(10-W28-X28))) | AC28: =IF(W28=0,"",ROUND((V28/W28)*10,0))
A29: Jace Ratliff | V29: =SUM(B29,D29,F29,H29,J29,L29,N29,P29,R29,T29) | W29: =COUNTIF(C29,"P")+COUNTIF(E29,"P")+COUNTIF(G29,"P")+COUNTIF(I29,"P")+COUNTIF(K29,"P")+COUNTIF(M29,"P")+COUNTIF(O29,"P")+COUNTIF(Q29,"P")+COUNTIF(S29,"P")+COUNTIF(U29,"P") | X29: =COUNTIF(C29,"A")+COUNTIF(E29,"A")+COUNTIF(G29,"A")+COUNTIF(I29,"A")+COUNTIF(K29,"A")+COUNTIF(M29,"A")+COUNTIF(O29,"A")+COUNTIF(Q29,"A")+COUNTIF(S29,"A")+COUNTIF(U29,"A") | Z29: =IF(Y29="","",Y29-V29) | AA29: =IF(OR(Y29="",Y29=0),"",V29/Y29) | AB29: =IF(OR(Y29="",Y29=0),"",IF((10-W29-X29)<=0,"N/A",Z29/(10-W29-X29))) | AC29: =IF(W29=0,"",ROUND((V29/W29)*10,0))
A30: Evan Allen | V30: =SUM(B30,D30,F30,H30,J30,L30,N30,P30,R30,T30) | W30: =COUNTIF(C30,"P")+COUNTIF(E30,"P")+COUNTIF(G30,"P")+COUNTIF(I30,"P")+COUNTIF(K30,"P")+COUNTIF(M30,"P")+COUNTIF(O30,"P")+COUNTIF(Q30,"P")+COUNTIF(S30,"P")+COUNTIF(U30,"P") | X30: =COUNTIF(C30,"A")+COUNTIF(E30,"A")+COUNTIF(G30,"A")+COUNTIF(I30,"A")+COUNTIF(K30,"A")+COUNTIF(M30,"A")+COUNTIF(O30,"A")+COUNTIF(Q30,"A")+COUNTIF(S30,"A")+COUNTIF(U30,"A") | Z30: =IF(Y30="","",Y30-V30) | AA30: =IF(OR(Y30="",Y30=0),"",V30/Y30) | AB30: =IF(OR(Y30="",Y30=0),"",IF((10-W30-X30)<=0,"N/A",Z30/(10-W30-X30))) | AC30: =IF(W30=0,"",ROUND((V30/W30)*10,0))
A31: Sai Neelagiri | V31: =SUM(B31,D31,F31,H31,J31,L31,N31,P31,R31,T31) | W31: =COUNTIF(C31,"P")+COUNTIF(E31,"P")+COUNTIF(G31,"P")+COUNTIF(I31,"P")+COUNTIF(K31,"P")+COUNTIF(M31,"P")+COUNTIF(O31,"P")+COUNTIF(Q31,"P")+COUNTIF(S31,"P")+COUNTIF(U31,"P") | X31: =COUNTIF(C31,"A")+COUNTIF(E31,"A")+COUNTIF(G31,"A")+COUNTIF(I31,"A")+COUNTIF(K31,"A")+COUNTIF(M31,"A")+COUNTIF(O31,"A")+COUNTIF(Q31,"A")+COUNTIF(S31,"A")+COUNTIF(U31,"A") | Z31: =IF(Y31="","",Y31-V31) | AA31: =IF(OR(Y31="",Y31=0),"",V31/Y31) | AB31: =IF(OR(Y31="",Y31=0),"",IF((10-W31-X31)<=0,"N/A",Z31/(10-W31-X31))) | AC31: =IF(W31=0,"",ROUND((V31/W31)*10,0))
A32: Fletcher Meese | V32: =SUM(B32,D32,F32,H32,J32,L32,N32,P32,R32,T32) | W32: =COUNTIF(C32,"P")+COUNTIF(E32,"P")+COUNTIF(G32,"P")+COUNTIF(I32,"P")+COUNTIF(K32,"P")+COUNTIF(M32,"P")+COUNTIF(O32,"P")+COUNTIF(Q32,"P")+COUNTIF(S32,"P")+COUNTIF(U32,"P") | X32: =COUNTIF(C32,"A")+COUNTIF(E32,"A")+COUNTIF(G32,"A")+COUNTIF(I32,"A")+COUNTIF(K32,"A")+COUNTIF(M32,"A")+COUNTIF(O32,"A")+COUNTIF(Q32,"A")+COUNTIF(S32,"A")+COUNTIF(U32,"A") | Z32: =IF(Y32="","",Y32-V32) | AA32: =IF(OR(Y32="",Y32=0),"",V32/Y32) | AB32: =IF(OR(Y32="",Y32=0),"",IF((10-W32-X32)<=0,"N/A",Z32/(10-W32-X32))) | AC32: =IF(W32=0,"",ROUND((V32/W32)*10,0))
